Workbook
Name X01523bc55cc9d7891758349de91063e5054bba0: 'VENTES 2026-30 – NEUF-RÉNO'!#REF!
Name X1c1027bec0843a5e4f94050f62561fd20c91d93: 'VENTES 2026-30 – NEUF-RÉNO'!#REF!
Name X9714d30f3be8d8aef2230409d030d0767b57939: 'VENTES 2026-30 – NEUF-RÉNO'!#REF!
Name Xbab138113ded3ce224050259b53b6ee0062ae07: 'VENTES 2026-30 – NEUF-RÉNO'!#REF!
Name Xd0f99639db72f25eeee83bcc1c064b9627c8eeb: 'VENTES 2026-30 – NEUF-RÉNO'!#REF!
Name Xe58082e289258386bd204de2e5aee637eb250e8: 'VENTES 2026-30 – NEUF-RÉNO'!#REF!

Sheet Périmètre TERTIAIRE
C2: Segment Principal | D2: Sous-Segment | E2: Exemples | Q2: Tous les Sous-Segments
B3: 75 | C3: Bureaux | D3: Bureaux Tertiaire Privé (>50 salariés) (hors usines et logistique ) | E3: Immeuble tertiaire privé, siège social, centre de services,etc … | Q3: Crèches
B4: 76 | C4: Logistique / Stockage | D4: Centres de stockage / Entrepôts / Plateformes logistiques (>50 salariés) | E4: Entrepôt, plateforme logistique, centre de distribution | Q4: Haltes-garderies, jardins d’enfants (hors crèches)
B5: 77 | C5: Usines & Ateliers | D5: Usines (>50 salariés) (Hors Ateliers industriels) | E5: Usine agroalimentaire, site métallurgique, usine chimique, usine automobile | Q5: Protection Maternelle et Infantile (PMI - sites autonomes)
B6: 78 | C6: Usines & Ateliers | D6: Ateliers industriels / de maintenance (>50 personnes) | E6: Atelier de maintenance, atelier technique, atelier industriel | Q6: Écoles maternelles
B7: 95 | C7: Administrations / services publics | D7: Bureaux administratifs secondaires non ERP >50 salariés | E7: sites de gestion interne >50 salariés, directions support sans accueil, back-offices administratifs de l’État, services techniques / RH / finances de collectivités, annexes administratives d’universités ou de rectorats, back-offices CPAM, CARSAT, ARS, MSA, CROUS, bâtiments administratifs hospitaliers séparés des zones patient/public | Q7: Écoles primaires
B8: 94 | C8: Administrations / services publics | D8: Mairies / hôtels de ville | E8: Mairie, hôtel de ville | Q8: Collèges (vestiaires EPS inclus)
B9: 96 | C9: Administrations / services publics | D9: Hôtels du département Hôtels de région & Services administratifs territoriaux | E9: Conseil départemental ; hôtel de région ; siège administratif territorial central | Q9: Lycées (vestiaires EPS inclus)
Q10: Internats scolaires
C11: Segment Principal | D11: Sous-Segment | E11: Exemples | Q11: Universités
B12: 72 | C12: Commerce | D12: Centres commerciaux / Malls | E12: Centre commercial, mall, galerie marchande gérée comme entité, retail park couvert avec sanitaires communs | Q12: Grandes écoles
B13: 74 | C13: Commerce | D13: Marchés couverts | E13: Marché couvert | Q13: Résidences étudiantes et dortoirs
Q14: Centres de formation / CFA
Q15: Agences emploi / Insertion / Orientation professionnelle
Q16: Gymnases / salles multisports (hors scolaire, mais gymnase municipaux inclus)
Q17: Salles de fitness / dojos
Q18: Patinoires couvertes
Q19: Piscines couvertes
Q20: Centres de thalassothérapie / balnéothérapie / grands spas ouverts au public
Q21: Établissements thermaux
Q22: Terrains de sport (Hors scolaire, sans tribune)
Q23: Stades avec tribunes (Hors grands stades, hors terrains sport)
Q24: Grands stades avec tribunes (Type football/rugby)
Q25: Hippodromes, Centres équestres & Manèges couverts
... Q149: Crématoriums

Sheet DATA - ANALYSE - TERTIAIRE
J1: Classement ERP | Q1: Comptage | AA1: 2015-20 | AF1: 2020-25 | AK1: 2025-30 | AO1: Argu Evolution | AT1: Detail Capacité par Public | AY1: Detail Dimensionnement | BF1: =BF7/$BD$7 -> 0.0023796976 | BG1: =BG7/$BD$7 -> 0.011452295 | BH1: =BH7/$BD$7 -> 0.04796578 | BN1: Volume Pièces | CQ1: Mix Type Pièces | DG1: Durée Vie - Type Pièces | DR1: Vol Lav 25-30 | EA1: Vol Douches 25-30 | EL1: Vol Urinoirs 25-30 | EU1: Vol WC 25-30 | EX1: =EX7/5000 -> 102.9739 | EY1: =FA7/5000 -> 95.31035 | EZ1: =EY1/$EX$1 -> 0.92557779 | FD1: 33-36% | FE1: =FG7/5000 -> 1.5515564 | FF1: =FE1/$EX$1 -> 0.015067473 | FG1: =FE1/$EY$1 -> 0.016278991 | FH1: 17-19% | FI1: =FJ7/5000 -> 5.7758638 | FJ1: =FI1/$EX$1 -> 0.056090563 | FK1: =FI1/$EY$1 -> 0.060600593 | FL1: 79-81% | FM1: Vtes Réno - Neuf | FR1: Fiabilité - Hypothèses | GG1: Potentiel-Projets-Dynamisme-Menaces | HX1: Réno-Neuf | IN1: Niveau de Confort - Global | KC1: Niveau de Confort - Type Pdt | KK1: Drivers - Tendances -Niveau de Confort
J2: Exemples | Q2: Fiabilité | AO2: 2025-2030 | BA2: Nombre Pièces - Robinetterie collectivité - Etablissements Recevant du Public - IMPERATIVEMENT dotés de sanitaires | BP2: Mix 2025 | BT2: Mix 2030 | BX2: Mix 2025 | CA2: Mix 2030 | CD2: Mix 2025 | CH2: Mix 2030 | CL2: Mix 2025 | CO2: Mix 2030 | CR2: Durée Vie réelle : Nbre Années effectives de vie produit avant remplacement | DI2: Volumes 2025 | DN2: Volumes 2030 | DT2: Volumes 2025 | DX2: Mix 2030 | EC2: Volumes 2025 | EH2: Mix 2030 | EN2: Volumes 2025 | ER2: Mix 2030 | EX2: Ventes 2026-2030 | FB2: Ventes 2026-2030 | FE2: Ventes 2026-2030 | FH2: Ventes 2026-2030 | FK2: Ventes 2026-2030 | FQ2: Ventes 2026-2030 | FS2: Dynamisme Ventes 2026-2030 | GI2: Ventes 2026-2030 | GL2: Ventes 2026-2030 | GO2: Ventes 2026-2030 | GR2: Ventes 2026-2030 | GU2: Ventes 2026-2030 | GX2: Ventes 2026-2030 | HA2: Ventes 2026-2030 | HD2: Ventes 2026-2030 | HG2: Ventes 2026-2030 | HJ2: Ventes 2026-2030 | HM2: Ventes 2026-2030 | HP2: Ventes 2026-2030 | HS2: Ventes 2026-2030 | HV2: Ventes 2026-2030 | IB2: Parc 2025 | IH2: Ventes 2026-2030 | IQ2: Parc 2025 | IV2: Ventes 2026-2030 | JA2: Parc 2025 | JF2: Ventes 2026-2030 | JK2: Parc 2025 | JP2: Ventes 2026-2030 | JU2: Parc 2025 | JZ2: Ventes 2026-2030 | KE2: Niveau
AF3: Nbre Etablissements | AZ3: par Etablissement | BE3: 2025 | BF3: Total 2025 | BJ3: 2030 | BK3: Total 2030 | BP3: Lavabo | BT3: Lavabo | BX3: Douches | CA3: Douches | CC3: Urinoirs - Chasse … | CG3: Urinoirs - Chasse … | CL3: WC - Chasse … | CO3: WC - Chasse … | CS3: Lavabo | CW3: Douches | CY3: Urinoirs - Chasse … | DD3: WC - Chasse … | DI3: Lavabo | DN3: Lavabo | DT3: Douches | DX3: Douches | EC3: Urinoirs - Chasse … | EH3: Urinoirs - Chasse … | EN3: WC - Chasse … | ER3: WC - Chasse … | EX3: Tous produits | FB3: Lavabos | FE3: Douches | FH3: Urinoirs | FK3: WC | FN3: Fiabilité | FQ3: Hypothèses Rénovation | FS3: Global | FU3: Renovation | FW3: Neuf brut | GI3: Lavabos - Mitigeurs | GL3: Lavabos - Tempo. méca | GO3: Lavabos - Tempo. électro | GR3: Lavabos - Autres | GU3: Douches - Mitigeurs | GX3: Douches - Tempo. méca | HA3: Douches - Tempo. électro | HD3: Urinoirs - à Réservoir | HG3: Urinoirs - Directe méca. | HJ3: Urinoirs - Directe électro indiv. | HM3: Urinoirs - Directe électro collect. | HP3: WC - à Réservoir | HS3: WC - Directe méca. | HV3: WC - Directe électro | IB3: Volumes - Toutes Pièces | IH3: Volumes - Toutes Pièces | IK3: Fiabilité | IQ3: Lavabos | IV3: Lavabos | JA3: Douches | JF3: Douches | JK3: Urinoirs | JP3: Urinoirs | JU3: WC | JZ3: WC | KD3: Incertitude | KF3: Fiabilité
A4: ID | B4: Catégorie chapeau | C4: Segment Principal | D4: Sous-Segment | E4: Type ERP principal | F4: Type de classement | G4: ERP Hors ERP Mixte | H4: Accueil Public : oui/non variable | I4: Notes de classement | J4: Exemples | K4: Présence de sommeil (oui-non variable) | L4: Espaces sanitaires collectifs (WC et/ou douche) | M4: Unité de compte retenue | N4: Nature de la donnée | O4: Niveau de fiabilité | P4: Sous-catégorie incluse dans … | Q4: Inclure dans Total France (1/0) | R4: Surface moyenne 2026 (m²/étab.) | S4: 2000 | T4: 2005 | U4: 2010 | V4: 2015 | W4: 2016 | X4: 2017 | Y4: 2018 | Z4: 2019 | AA4: 2020 | AB4: 2021 | AC4: 2022 | AD4: 2023 | AE4: 2024 | AF4: 2025 | AG4: 2026 | AH4: 2027 | AI4: 2028 | AJ4: 2029 | AK4: 2030 | AL4: Justification Taille Parc & Evolution-Variation 2026-2030 | AM4: Calculs & Sources - Taille Parc & Evolution-Variation 2026-2030 | AN4: Sources (URL) | AP4: Capacité instantanée Moyenne 2026 TOTAL | AQ4: Capacité instantanée Moyenne 2026 Usagers Principaux | AR4: Capacité instantanée Moyenne 2026 Staff | AS4: Capacité instantanée Moyenne 2026 Autre Public | AU4: Dimensionnement sanitaire retenu par Etablissement Sanitaires collectifs >5 pers. Sanitaires individuels uniquement pour Univers Carcéral, Santé, EHPAD-USLD | AV4: Argumentaire détaillé (Dimensionnement unitaire + Hypothèse d'usage) | AW4: Pondération terrain / Hypothèse d’usage | AX4: Sources de dimensionnement (URL / références) | AZ4: Lavabos | BA4: Douches | BB4: Urinoirs | BC4: WC | BD4: TOTAL Pièces | BE4: TOTAL Lavabos | BF4: Douches | BG4: Urinoirs | BH4: WC | BI4: TOTAL Pièces | BJ4: TOTAL Lavabos | BK4: Douches | BL4: Urinoirs | BM4: WC | BO4: Mitigeurs | BP4: Tempo. Méca | BQ4: Tempo. Electro | BR4: Autres | BS4: Mitigeurs | BT4: Tempo. Méca | BU4: Tempo. Electro | BV4: Autres | BW4: Mitigeurs | BX4: Tempo. Méca | BY4: Tempo. Electro | BZ4: Mitigeurs | CA4: Tempo. Méca | CB4: Tempo. Electro | CC4: à Réservoir | CD4: Directe méca. | CE4: Directe electro indiv | CF4: Directe electro collect. | CG4: à Réservoir | CH4: Directe méca. | CI4: Directe electro indiv | CJ4: Directe electro collect. | CK4: à Réservoir | CL4: Directe mécanique | CM4: Directe electro | CN4: à Réservoir | CO4: Directe mécanique | CP4: Directe electro | CR4: Mitigeurs | CS4: Tempo. Méca | CT4: Tempo. Electro | CU4: Autres | CV4: Mitigeurs | CW4: Tempo. Méca | CX4: Tempo. Electro | CY4: à Réservoir | CZ4: Directe méca. | DA4: Directe electro indiv | DB4: Directe electro collect. | DC4: à Réservoir | DD4: Directe mécanique | DE4: Directe electro | DF4: Justification Durée de Vie réelle | DH4: Mitigeurs | DI4: Tempo. Méca | DJ4: Tempo. Electro | DK4: Autres | DL4: Justification Mix Lavabos 2025 | DM4: Mitigeurs | DN4: Tempo. Méca | DO4: Tempo. Electro | DP4: Autres | DQ4: Évolution Lavabos 2025 → 2030 | DS4: Mitigeurs | DT4: Tempo. Méca | DU4: Tempo. Electro | DV4: Justification Mix Douches 2025 | DW4: Mitigeurs | DX4: Tempo. Méca | DY4: Tempo. Electro | DZ4: Évolution Douches 2025 → 2030 | EB4: à Réservoir | EC4: Directe méca. | ED4: Directe electro indiv | EE4: Directe electro collect. | EF4: Justification Mix Urinoirs 2025 | EG4: à Réservoir | EH4: Directe méca. | EI4: Directe electro indiv | EJ4: Directe electro collect. | EK4: Évolution Urinoirs 2025 → 2030 | EM4: à Réservoir | EN4: Directe méca. | EO4: Directe electro | EP4: Justification Mix WC 2025 | EQ4: à Réservoir | ER4: Directe méca. | ES4: Directe electro | ET4: Évolution WC 2025→2030 | EV4: Split Rénovation % | EW4: Split Neuf % | EX4: Total | EY4: Rénovation | EZ4: Neuf brut | FA4: Total | FB4: Rénovation | FC4: Neuf brut | FD4: Total | FE4: Rénovation | FF4: Neuf brut | FG4: Total | FH4: Rénovation | FI4: Neuf brut | FJ4: Total | FK4: Rénovation | FL4: Neuf brut | FN4: Split % Rénovation vs. Neuf | FO4: Hypothèse % Parc 2025 rénové | FP4: Hypothèse % Réalisat° Travaux Réno | FQ4: Justification % Réalisation | FS4: Score Global (sur 5) | FT4: Classement Global sur 147 sous-segm. | FU4: Score Renovation (sur 5) | FV4: Classement sur 103 Sous-Segments | FW4: Score Neuf brut (sur 5) | FX4: Classement sur 103 Sous-Segments | FZ4: Rénovation Potentiel 2026-2030 | GA4: Neuf Potentiel 2026-2030 | GB4: Rénovation Projets Phares Programmes & Exemples 2026-2030 | GC4: Neuf Projets Phares Programmes & Exemples 2026-2030 | GD4: Rénovation Dynamique & Menaces 2026-2030 | GE4: Neuf Dynamique & Menaces 2026-2030 | GF4: Neuf & Rénovation Ventes - Dynamique & Menaces Sources & URL 2026-2030 | GH4: Total | GI4: Rénovation | GJ4: Neuf brut | GK4: Total | GL4: Rénovation | GM4: Neuf brut | GN4: Total | GO4: Rénovation | GP4: Neuf brut | GQ4: Total | GR4: Rénovation | GS4: Neuf brut | GT4: Total | GU4: Rénovation | GV4: Neuf brut | GW4: Total | GX4: Rénovation | GY4: Neuf brut | GZ4: Total | HA4: Rénovation | HB4: Neuf brut | HC4: Total | HD4: Rénovation | HE4: Neuf brut | HF4: Total | HG4: Rénovation | HH4: Neuf brut | HI4: Total | HJ4: Rénovation | HK4: Neuf brut | HL4: Total | HM4: Rénovation | HN4: Neuf brut | HO4: Total | HP4: Rénovation | HQ4: Neuf brut | HR4: Total | HS4: Rénovation | HT4: Neuf brut | HU4: Total | HV4: Rénovation | HW4: Neuf brut | HY4: Total Volumes Parc 2025 | HZ4: Entrée | IA4: Basique | IB4: Moyen | IC4: Premium | ID4: Luxe | IE4: Total Volumes Ventes 2026-2030 | IF4: Entrée | IG4: Basique | IH4: Moyen | II4: Premium | IJ4: Luxe | IK4: Score Global (sur 5) | IL4: Appréciation | IM4: Segmentation par Niveau de Confort Commentaires | IO4: Entrée | IP4: Basique | IQ4: Moyen | IR4: Premium | IS4: Luxe | IT4: Entrée | IU4: Basique | IV4: Moyen | IW4: Premium | IX4: Luxe | IY4: Entrée | IZ4: Basique | JA4: Moyen | JB4: Premium | JC4: Luxe | JD4: Entrée | JE4: Basique | JF4: Moyen | JG4: Premium | JH4: Luxe | JI4: Entrée | JJ4: Basique | JK4: Moyen | JL4: Premium | JM4: Luxe | JN4: Entrée | JO4: Basique | JP4: Moyen | JQ4: Premium | JR4: Luxe | JS4: Entrée | JT4: Basique | JU4: Moyen | JV4: Premium | JW4: Luxe | JX4: Entrée | JY4: Basique | JZ4: Moyen | KA4: Premium | KB4: Luxe | KD4: Parc | KE4: Ventes 2026-2030 | KF4: Score Global (sur 5) | KG4: Appréciation | KH4: Drivers Parc existant | KI4: Tendances Ventes 2026-2030 | KJ4: Drivers Ventes 2026-2030
A5: - | B5: - | C5: - | D5: - | E5: - | F5: - | G5: - | H5: - | I5: - | J5: - | K5: - | L5: - | M5: - | N5: - | O5: - | P5: - | Q5: - | R5: - | S5: - | T5: - | U5: - | V5: - | W5: - | X5: - | Y5: - | Z5: - | AA5: - | AB5: - | AC5: - | AD5: - | AE5: - | AF5: - | AG5: - | AH5: - | AI5: - | AJ5: - | AK5: - | AL5: - | AM5: - | AN5: - | AP5: - | AQ5: - | AR5: - | AS5: - | AU5: - | AV5: - | AW5: - | AX5: - | AZ5: - | BA5: - | BB5: - | BC5: - | BE5: - | BF5: - | BG5: - | BH5: - | BJ5: - | BK5: - | BL5: - | BM5: - | BO5: - | BP5: - | BQ5: - | BR5: - | BS5: - | BT5: - | BU5: - | BV5: - | BW5: - | BX5: - | BY5: - | BZ5: - | CA5: - | CB5: - | CC5: - | CD5: - | CE5: - | CF5: - | CG5: - | CH5: - | CI5: - | CJ5: - | CK5: - | CL5: - | CM5: - | CN5: - | CO5: - | CP5: - | CR5: - | CS5: - | CT5: - | CU5: - | CV5: - | CW5: - | CX5: - | CY5: - | CZ5: - | DA5: - | DB5: - | DC5: - | DD5: - | DE5: - | DF5: - | DH5: - | DI5: - | DJ5: - | DK5: - | DL5: - | DM5: - | DN5: - | DO5: - | DP5: - | DQ5: - | DS5: - | DT5: - | DU5: - | DV5: - | DW5: - | DX5: - | DY5: - | DZ5: - | EB5: - | EC5: - | ED5: - | EE5: - | EF5: - | EG5: - | EH5: - | EI5: - | EJ5: - | EK5: - | EM5: - | EN5: - | EO5: - | EP5: - | EQ5: - | ER5: - | ES5: - | ET5: - | EV5: - | EW5: - | EX5: - | EY5: - | EZ5: - | FA5: - | FB5: - | FC5: - | FD5: - | FE5: - | FF5: - | FG5: - | FH5: - | FI5: - | FJ5: - | FK5: - | FL5: - | FN5: - | FO5: - | FP5: - | FQ5: - | FS5: - | FT5: - | FU5: - | FV5: - | FW5: - | FX5: - | FZ5: - | GA5: - | GB5: - | GC5: - | GD5: - | GE5: - | GF5: - | GH5: - | GI5: - | GJ5: - | GK5: - | GL5: - | GM5: - | GN5: - | GO5: - | GP5: - | GQ5: - | GR5: - | GS5: - | GT5: - | GU5: - | GV5: - | GW5: - | GX5: - | GY5: - | GZ5: - | HA5: - | HB5: - | HC5: - | HD5: - | HE5: - | HF5: - | HG5: - | HH5: - | HI5: - | HJ5: - | HK5: - | HL5: - | HM5: - | HN5: - | HO5: - | HP5: - | HQ5: - | HR5: - | HS5: - | HT5: - | HU5: - | HV5: - | HW5: - | HY5: - | HZ5: - | IA5: - | IB5: - | IC5: - | ID5: - | IE5: - | IF5: - | IG5: - | IH5: - | II5: - | IJ5: - | IK5: - | IL5: - | IM5: - | IO5: - | IP5: - | IQ5: - | IR5: - | IS5: - | IT5: - | IU5: - | IV5: - | IW5: - | IX5: - | IY5: - | IZ5: - | JA5: - | JB5: - | JC5: - | JD5: - | JE5: - | JF5: - | JG5: - | JH5: - | JI5: - | JJ5: - | JK5: - | JL5: - | JM5: - | JN5: - | JO5: - | JP5: - | JQ5: - | JR5: - | JS5: - | JT5: - | JU5: - | JV5: - | JW5: - | JX5: - | JY5: - | JZ5: - | KA5: - | KB5: - | KD5: - | KE5: - | KF5: - | KG5: - | KH5: - | KI5: - | KJ5: -
C6: TOTAL (Etablissements dotés de sanitaires) | Q6: Total additionne lignes = 1 | R6: 2459.1609 | S6: 565272 | T6: 581449 | U6: 597349 | V6: 614886 | W6: 617900 | X6: 620576 | Y6: 624783 | Z6: 628795 | AA6: 620409 | AB6: 620075 | AC6: 626768 | AD6: 631586 | AE6: 636661 | AF6: 638960 | AG6: 640919 | AH6: 643045 | AI6: 644975 | AJ6: 646524 | AK6: 647940 | AP6: 153.69949 | AQ6: 135.28077 | AR6: 18.072976 | AS6: 5.503625 | AU6: Moyenne pondérée / total France | AV6: Synthèse pondérée France : sanitaires collectifs >5 pers., hors individuels sauf EHPAD/USLD. | AW6: Méthode : partir d’1 minimum sanitaire réaliste, ajusté selon taille, fréquentat° probable, puis appliquer 1 moyenne pondérée terrain (éviter qu’1 cas extrême biaise le sous-segment). Enfin, correct° selon intensité d’usage : passage court, usage quotidien, activité salissante, sport, soins, etc. | AX6: Références réglementaires, guides sectoriels et hypothèses de programmation utilisés pour le programme sanitaire unitaire. | AZ6: 9.9092186 | BA6: 2.7928842 | BB6: 1.6893713 | BC6: 8.07789 | BD6: 14135454 | BE6: 6233879.5 | BF6: 1757000.7 | BG6: 1062781.8 | BH6: 5081792.5 | BI6: 14272046 | BJ6: 6286026 | BK6: 1785842.1 | BL6: 1076541.8 | BM6: 5123636 | BO6: 0.29347467 | BP6: 0.55310218 | BQ6: 0.090947093 | BR6: 0.062476062 | BS6: 0.26362949 | BT6: 0.55885723 | BU6: 0.12087746 | BV6: 0.056635824 | BW6: 0.41385698 | BX6: 0.52808505 | BY6: 0.058057969 | BZ6: 0.37053944 | CA6: 0.55537764 | CB6: 0.074082915 | CC6: 0.087658912 | CD6: 0.55163276 | CE6: 0.11869938 | CF6: 0.24200895 | CG6: 0.072051819 | CH6: 0.5514006 | CI6: 0.1445451 | CJ6: 0.23200247 | CK6: 0.56671172 | CL6: 0.33220462 | CM6: 0.10108366 | CN6: 0.484449 | CO6: 0.36720729 | CP6: 0.14834372 | CR6: 12.426523 | CS6: 12.436186 | CT6: 9.0251239 | CU6: 10.896039 | CV6: 11.170059 | CW6: 9.6816619 | CX6: 8.0591967 | CY6: 10.149214 | CZ6: 12.075347 | DA6: 8.4200242 | DB6: 10.089803 | DC6: 12.474018 | DD6: 12.52315 | DE6: 9.1658181 | DF6: La durée de vie réelle dépend surtout de l’usage, de la maintenance, du vandalisme et du mode de rénovation, plus que de la durée théorique fabricant. Plus courte dans les sites à fort trafic ou à fortes contraintes d’hygiène, plus longue dans les environnements plus calmes. Les équipements mécaniques robustes tiennent souvent bien dans les usages intensifs, tandis que les solutions électroniques peuvent être renouvelées plus tôt pour raisons de capteurs, batteries, électrovannes ou modernisation. Part importante des remplacements se fait par lots ou lors de rénovations, pas seulement à la panne. | DH6: 1829485.7 | DI6: 3447972.3 | DJ6: 566953.22 | DK6: 389468.24 | DL6: La temporisation mécanique reste structurante dans les parcs intensifs ; la bascule 2025→2030 se fait surtout au profit de l'électronique sur les rénovations lourdes et les bâtiments tertiaires/publics. | DM6: 1657181.8 | DN6: 3512991.1 | DO6: 759838.84 | DP6: 356014.26 | DQ6: Dominant, le mitigeur recule, à chaque rénovation prévue et en neuf. Le tempo méca. résiste bien (vs. électro=> budget, installat°, entretien), mais électronique remplace en grande majorité le mitigeur (à nuancer en fonction du type d'ERP). | DS6: 727147 | DT6: 927845.79 | DU6: 102007.89 | DV6: Parc dominé par le tempo. mécanique et distance en nombre les mitigeurs. Electronique 5 à 6 fois moins représenté (que mécanique) => usage plus long, détection moins fiable que lavabo, moins de confort thermique potentiel. | DW6: 661724.92 | DX6: 991816.75 | DY6: 132300.39 | DZ6: Hausse 'électronique plus graduelle (qu'en lavabo) et variable selon ERP (exemple : plus forte sur tertiaire, commerce, que sur univers carcéral). | EB6: 93162.296 | EC6: 586265.26 | ED6: 126151.54 | EE6: 257202.71 | EF6: Parc dominé par tempo méca : robustesse, simplicité, adaptation aux usages intensifs. Electronique progresse mais reste minoritaire, freinée par contraintes maintenance/coût. | EG6: 77566.791 | EH6: 593605.77 | EI6: 155608.84 | EJ6: 249760.35 | EK6: Part temporisé électro. augmente légèrement => enjeux hygiène sans contact + maîtrise de conso. eau. Mécanique recule légèrement mais reste majoritaire => fiabilité en usage intensif. | EM6: 2879911.4 | EN6: 1688194.9 | EO6: 513686.17 | EP6: Parc WC repose surtout sur systèmes gravitaires, mécaniques, robustes, économiques, faciles à maintenir. Electronique secondaire mais présent dans lieux premium ou à forte exigence sanitaire. | EQ6: 2482140.3 | ER6: 1881436.5 | ES6: 760059.2 | ET6: Electronique gagne du terrain, surtout sur ERP récents-rénovés => exigences hygiène + automatisation => Progression faible : solutions méca conservent avantage coût/fiabilité. | EV6: 0.79594964 | EW6: 0.20405036 | EX6: 5821049.3 | EY6: 4633262.1 | EZ6: 1187787.2 | FA6: 2501271.8 | FB6: 1987652.9 | FC6: 513618.91 | FD6: 862826.07 | FE6: 697568.46 | FF6: 165257.61 | FG6: 451286.19 | FH6: 360063.11 | FI6: 91223.077 | FJ6: 2005665.2 | FK6: 1587977.6 | FL6: 417687.61 | FN6: Agrégat Pondéré | FO6: 0.060675716 | FP6: 0.82880687 | FQ6: Taux moyen pondéré France de matérialisation des travaux sur 2026-2030. | FS6: 3.19 | FT6: - | FU6: 3.97 | FV6: - | FW6: 2.24 | FX6: - | FZ6: La rénovation domine et reste plus résiliente que le neuf, dépendant moins de créations nettes d’établissements que de cycles de remplacement incompressibles, de remises à niveau d’hygiène/usage et de travaux diffus sur un parc installé très vaste et largement assujetti à des cycles de remplacement / mise à niveau. Sous-segments phares => Restaurants, EHPAD, Bureaux >50 pers., Écoles primaires, Gymnases, Salles multisports et Mairies. | GA6: Neuf plus sélectif, dépendant des cycles économiques, porté par créations d’établissements + programmes publics-privés (santé, sport, France services, industrie, carcéral, aéroports). Rythme plus volatil, concentré sur projets structurants. Sous-segments phares en neuf => Bureaux, EHPAD, Hôtels, Enseignement supérieur, Santé, Equipements sportifs. | GB6: Fonds vert / EduRénov ; Modernisation Hôpitaux (Ségur phase 2), Plan CNSA (réhab. EHPAD ; Normes accessibilité (Ad’AP)), Réno 5000 équipements sportifs (JO héritage) ; Loi de Programmation Militaire ; Transformation tertiaire ESG, France services. | GC6: Prison : plan 15 000 places, Grands projets touristiques (resorts, parcs), Nouveaux hôpitaux + CHU (reconstructions), Cliniques privées + Pôles santé, Maisons de santé pluriprofessionnelles, Campus universitaires, Learning centers, Nouveaux terminaux aéroport, Logistique, entrepôts. | GD6: Soutenue par décret Éco Énergie Tertiaire (EET) + Age avancé du parc + Logiques d’interventions par lots (sanitaires dans projets + larges : énergie, accessibilité, mise normes). Socle Investissements publics stable + Obligations réglementaires progressives => Marché résilient, diffus, peu dépendant de cycles économiques courts | GE6: Dynamique positive, concentrée sur filières motrices (santé, enseignement sup, segments tertiaires). Forte dépendance : arbitrage budget public, décision invest. privé. Sensible => cycles éco, condit° financement, délais réalisat°. Ecart fréquent intentions vs. livraisons réelles => croissance + volatile - homogène, ciblée géographiquement | GF6: https://www.ecologie.gouv.fr/eco-energie-tertiaire-eet https://www.info.gouv.fr/actualite/segur-de-la-sante-de-nouveaux-investissements-pour-l-hopital https://www.cnsa.fr/budget-et-financement/financement-des-esms/investissement-immobilier https://www.agencedusport.fr/plan-5000-equipements-generation-2024 https://www.france-services.gouv.fr/actualites/labellisation-nouvelles-maisons-france-services https://www.justice.gouv.fr/plan-15-000-places-prison https://www.defense.gouv.fr/ministere/politique-defense/loi-programmation-militaire-2024-2030 https://www.economie.gouv.fr/cedef/reindustrialisation-informations https://presse.groupeadp.fr/proposition-cre2027-2034/ https://www.garesetconnexions.sncf/fr/qui-sommes-nous/notre-modele-economique | GH6: 703546.04 | GI6: 576270.71 | GJ6: 127275.33 | GK6: 1315637.7 | GL6: 1024124.4 | GM6: 291513.26 | GN6: 310328.85 | GO6: 245464.56 | GP6: 64864.283 | GQ6: 171759.21 | GR6: 141793.16 | GS6: 29966.045 | GT6: 331189.47 | GU6: 271650.49 | GV6: 59538.982 | GW6: 472158.1 | GX6: 378940.83 | GY6: 93217.269 | GZ6: 59478.5 | HA6: 46977.145 | HB6: 12501.355 | HC6: 39711.426 | HD6: 33444.328 | HE6: 6267.0977 | HF6: 227932.93 | HG6: 177829.86 | HH6: 50103.07 | HI6: 69612.421 | HJ6: 55617.713 | HK6: 13994.708 | HL6: 114029.42 | HM6: 93171.215 | HN6: 20858.201 | HO6: 1055388.4 | HP6: 860683.44 | HQ6: 194705 | HR6: 662715.51 | HS6: 503979.11 | HT6: 158736.4 | HU6: 287561.26 | HV6: 223315.05 | HW6: 64246.205 | HY6: 14135454 | HZ6: 865403.9 | IA6: 5140157.6 | IB6: 5839913 | IC6: 2040655.4 | ID6: 249324.51 | IE6: 4633262.1 | IF6: 120886.16 | IG6: 1189421.2 | IH6: 2105519.2 | II6: 1040079.9 | IJ6: 177355.61 | IK6: 3.86 | IL6: Bonne | IO6: 0.0507 | IP6: 0.3489 | IQ6: 0.4319 | IR6: 0.1497 | IS6: 0.0188 | IT6: 0.02 | IU6: 0.2326 | IV6: 0.4683 | IW6: 0.2376 | IX6: 0.0415 | IY6: 0.072 | IZ6: 0.3519 | JA6: 0.384 | JB6: 0.1679 | JC6: 0.0242 | JD6: 0.0355 | JE6: 0.2767 | JF6: 0.4095 | JG6: 0.2317 | JH6: 0.0466 | JI6: 0.1234 | JJ6: 0.4706 | JK6: 0.3199 | JL6: 0.0759 | JM6: 0.0102 | JN6: 0.056 | JO6: 0.3741 | JP6: 0.4166 | JQ6: 0.1327 | JR6: 0.0206 | JS6: 0.0574 | JT6: 0.3634 | JU6: 0.4197 | JV6: 0.144 | JW6: 0.0155 | JX6: 0.0228 | JY6: 0.2515 | JZ6: 0.4654 | KA6: 0.2257 | KB6: 0.0346 | KD6: ±4 pts | KE6: ±5 pts | KF6: 4.15 | KG6: Bonne | KH6: Agrégation volume × mix par sous-segment ; les gros gisements (bureaux, écoles, santé, sport, hôtels, transports) pèsent davantage dans le total que les niches. | KI6: Total France pondéré par volumes 2025 et ventes 2026-2030 ; forte fréquentation tire le standard, image/privé tire premium, contrainte sanitaire renforce surtout le milieu de gamme technique. | KJ6: Agrégation volume × ventes 2026-2030 ; le neuf et les rénovations lourdes tirent le mix vers l’moyen/premium, mais la rénovation majoritaire garde un centre de gravité basique/moyen.
B7: TOTAL | C7: TERITAIRE (ci-dessous) | Q7: Total additionne lignes = 1 | R7: =IFERROR(SUMPRODUCT($Q$16:$Q$17,$AG$16:$AG$17,R$16:R$17)/SUMPRODUCT($Q$16:$Q$17,$AG$16:$AG$17),"") -> 22400.881 | S7: =SUMPRODUCT($Q$16:$Q$17,S$16:S$17) -> 1150 | T7: =SUMPRODUCT($Q$16:$Q$17,T$16:T$17) -> 1180 | U7: =SUMPRODUCT($Q$16:$Q$17,U$16:U$17) -> 1210 | V7: =SUMPRODUCT($Q$16:$Q$17,V$16:V$17) -> 1245 | W7: =SUMPRODUCT($Q$16:$Q$17,W$16:W$17) -> 1260 | X7: =SUMPRODUCT($Q$16:$Q$17,X$16:X$17) -> 1275 | Y7: =SUMPRODUCT($Q$16:$Q$17,Y$16:Y$17) -> 1290 | Z7: =SUMPRODUCT($Q$16:$Q$17,Z$16:Z$17) -> 1305 | ... AE7: =SUMPRODUCT($Q$16:$Q$17,AE$16:AE$17) -> 1344 | AF7: =SUM(AF9:AF17) -> 94469 | AG7: =SUMPRODUCT($Q$16:$Q$17,AG$16:AG$17) -> 1362 | AH7: =SUMPRODUCT($Q$16:$Q$17,AH$16:AH$17) -> 1372 | AI7: =SUMPRODUCT($Q$16:$Q$17,AI$16:AI$17) -> 1382 | AJ7: =SUMPRODUCT($Q$16:$Q$17,AJ$16:AJ$17) -> 1392 | AK7: =SUM(AK9:AK17) -> 94614 | AP7: =IFERROR(SUMPRODUCT($Q$16:$Q$17,$AG$16:$AG$17,AP$16:AP$17)/SUMPRODUCT($Q$16:$Q$17,$AG$16:$AG$17),"") -> 2298.2379 | AQ7: =IFERROR(SUMPRODUCT($Q$16:$Q$17,$AF$16:$AF$17,AQ$16:AQ$17)/SUMPRODUCT($Q$16:$Q$17,$AF$16:$AF$17),"") -> 1886.1538 | AR7: =IFERROR(SUMPRODUCT($Q$16:$Q$17,$AF$16:$AF$17,AR$16:AR$17)/SUMPRODUCT($Q$16:$Q$17,$AF$16:$AF$17),"") -> 300 | AS7: =IFERROR(SUMPRODUCT($Q$16:$Q$17,$AF$16:$AF$17,AS$16:AS$17)/SUMPRODUCT($Q$16:$Q$17,$AF$16:$AF$17),"") -> 121.53846 | AU7: Moyenne pondérée / total France | AV7: Synthèse pondérée France : sanitaires collectifs >5 pers., hors individuels sauf EHPAD/USLD. | AW7: Méthode : partir d’1 minimum sanitaire réaliste, ajusté selon taille, fréquentat° probable, puis appliquer 1 moyenne pondérée terrain (éviter qu’1 cas extrême biaise le sous-segment). Enfin, correct° selon intensité d’usage : passage court, usage quotidien, activité salissante, sport, soins, etc. | AX7: Références réglementaires, guides sectoriels et hypothèses de programmation utilisés pour le programme sanitaire unitaire. | AZ7: =IFERROR(SUMPRODUCT($Q$16:$Q$17,$AF$16:$AF$17,AZ$16:AZ$17)/SUMPRODUCT($Q$16:$Q$17,$AF$16:$AF$17),"") -> 53.076923 | BA7: =IFERROR(SUMPRODUCT($Q$16:$Q$17,$AF$16:$AF$17,BA$16:BA$17)/SUMPRODUCT($Q$16:$Q$17,$AF$16:$AF$17),"") -> 2.4615385 | BB7: =IFERROR(SUMPRODUCT($Q$16:$Q$17,$AF$16:$AF$17,BB$16:BB$17)/SUMPRODUCT($Q$16:$Q$17,$AF$16:$AF$17),"") -> 11.846154 | BC7: =IFERROR(SUMPRODUCT($Q$16:$Q$17,$AF$16:$AF$17,BC$16:BC$17)/SUMPRODUCT($Q$16:$Q$17,$AF$16:$AF$17),"") -> 49.615385 | BD7: =SUM(BE7:BH7) -> 1398497 | BE7: =SUM(BE9:BE17) -> 1312073 | BF7: =SUMPRODUCT($Q$16:$Q$17,BF$16:BF$17) -> 3328 | BG7: =SUMPRODUCT($Q$16:$Q$17,BG$16:BG$17) -> 16016 | BH7: =SUMPRODUCT($Q$16:$Q$17,BH$16:BH$17) -> 67080 | BI7: =SUM(BJ7:BM7) -> 1403350 | BJ7: =SUM(BJ9:BJ17) -> 1315225 | BK7: =SUMPRODUCT($Q$16:$Q$17,BK$16:BK$17) -> 3380 | BL7: =SUMPRODUCT($Q$16:$Q$17,BL$16:BL$17) -> 16330 | BM7: =SUMPRODUCT($Q$16:$Q$17,BM$16:BM$17) -> 68415 | BO7: =DH7/$BE7 -> 0.41255101 | BP7: =DI7/$BE7 -> 0.38172798 | BQ7: =DJ7/$BE7 -> 0.15714024 | BR7: =DK7/$BE7 -> 0.048580773 | BS7: =DM7/$BJ7 -> 0.35908327 | BT7: =DN7/$BJ7 -> 0.38969085 | BU7: =DO7/$BJ7 -> 0.21378061 | BV7: =DP7/$BJ7 -> 0.037445266 | BW7: =DS7/$BF7 -> 0.45 | BX7: =DT7/$BF7 -> 0.45 | BY7: =DU7/$BF7 -> 0.1 | BZ7: =DW7/$BK7 -> 0.4 | CA7: =DX7/$BK7 -> 0.47 | CB7: =DY7/$BK7 -> 0.13 | CC7: =EB7/$BG7 -> 0.10324675 | CD7: =EC7/$BG7 -> 0.55 | CE7: =ED7/$BG7 -> 0.1 | CF7: =EE7/$BG7 -> 0.24675325 | CG7: =EG7/$BL7 -> 0.083429271 | CH7: =EH7/$BL7 -> 0.55 | CI7: =EI7/$BL7 -> 0.12931415 | CJ7: =EJ7/$BL7 -> 0.23725658 | CK7: =EM7/$BH7 -> 0.50348837 | CL7: =EN7/$BH7 -> 0.34651163 | CM7: =EO7/$BH7 -> 0.15 | CN7: =EQ7/$BM7 -> 0.4036834 | CO7: =ER7/$BM7 -> 0.39484324 | CP7: =ES7/$BM7 -> 0.20147336 | CR7: =IFERROR(SUMPRODUCT(DH$16:DH$17,CR$16:CR$17)/SUM(DH$16:DH$17),"") -> 10.815603 | CS7: =IFERROR(SUMPRODUCT(DI$16:DI$17,CS$16:CS$17)/SUM(DI$16:DI$17),"") -> 11.933549 | CT7: =IFERROR(SUMPRODUCT(DJ$16:DJ$17,CT$16:CT$17)/SUM(DJ$16:DJ$17),"") -> 8 | CU7: =IFERROR(SUMPRODUCT(DK$16:DK$17,CU$16:CU$17)/SUM(DK$16:DK$17),"") -> 9.9275362 | CV7: =IFERROR(SUMPRODUCT(DS$16:DS$17,CV$16:CV$17)/SUM(DS$16:DS$17),"") -> 10 | CW7: =IFERROR(SUMPRODUCT(DT$16:DT$17,CW$16:CW$17)/SUM(DT$16:DT$17),"") -> 9 | CX7: =IFERROR(SUMPRODUCT(DU$16:DU$17,CX$16:CX$17)/SUM(DU$16:DU$17),"") -> 7 | CY7: =IFERROR(SUMPRODUCT(EB$16:EB$17,CY$16:CY$17)/SUM(EB$16:EB$17),"") -> 8.9056604 | CZ7: =IFERROR(SUMPRODUCT(EC$16:EC$17,CZ$16:CZ$17)/SUM(EC$16:EC$17),"") -> 11 | DA7: =IFERROR(SUMPRODUCT(ED$16:ED$17,DA$16:DA$17)/SUM(ED$16:ED$17),"") -> 7.0649351 | DB7: =IFERROR(SUMPRODUCT(EE$16:EE$17,DB$16:DB$17)/SUM(EE$16:EE$17),"") -> 9 | DC7: =IFERROR(SUMPRODUCT(EM$16:EM$17,DC$16:DC$17)/SUM(EM$16:EM$17),"") -> 11.771363 | DD7: =IFERROR(SUMPRODUCT(EN$16:EN$17,DD$16:DD$17)/SUM(EN$16:EN$17),"") -> 12 | DE7: =IFERROR(SUMPRODUCT(EO$16:EO$17,DE$16:DE$17)/SUM(EO$16:EO$17),"") -> 8.0697674 | DF7: La durée de vie réelle dépend surtout de l’usage, de la maintenance, du vandalisme et du mode de rénovation, plus que de la durée théorique fabricant. Plus courte dans les sites à fort trafic ou à fortes contraintes d’hygiène, plus longue dans les environnements plus calmes. Les équipements mécaniques robustes tiennent souvent bien dans les usages intensifs, tandis que les solutions électroniques peuvent être renouvelées plus tôt pour raisons de capteurs, batteries, électrovannes ou modernisation. Part importante des remplacements se fait par lots ou lors de rénovations, pas seulement à la panne. | DH7: =SUM(DH9:DH17) -> 541297.04 | DI7: =SUM(DI9:DI17) -> 500854.98 | DJ7: =SUM(DJ9:DJ17) -> 206179.46 | DK7: =SUM(DK9:DK17) -> 63741.52 | DM7: =SUM(DM9:DM17) -> 472275.3 | DN7: =SUM(DN9:DN17) -> 512531.15 | DO7: =SUM(DO9:DO17) -> 281169.6 | DP7: =SUM(DP9:DP17) -> 49248.95 | DS7: =SUMPRODUCT($Q$16:$Q$17,DS$16:DS$17) -> 1497.6 | DT7: =SUMPRODUCT($Q$16:$Q$17,DT$16:DT$17) -> 1497.6 | DU7: =SUMPRODUCT($Q$16:$Q$17,DU$16:DU$17) -> 332.8 | DV7: Parc dominé par le tempo. mécanique et distance en nombre les mitigeurs. Electronique 5 à 6 fois moins représenté (que mécanique) => usage plus long, détection moins fiable que lavabo, moins de confort thermique potentiel. | DW7: =SUMPRODUCT($Q$16:$Q$17,DW$16:DW$17) -> 1352 | DX7: =SUMPRODUCT($Q$16:$Q$17,DX$16:DX$17) -> 1588.6 | DY7: =SUMPRODUCT($Q$16:$Q$17,DY$16:DY$17) -> 439.4 | DZ7: Hausse 'électronique plus graduelle (qu'en lavabo) et variable selon ERP (exemple : plus forte sur tertiaire, commerce, que sur univers carcéral). | EB7: =SUMPRODUCT($Q$16:$Q$17,EB$16:EB$17) -> 1653.6 | EC7: =SUMPRODUCT($Q$16:$Q$17,EC$16:EC$17) -> 8808.8 | ED7: =SUMPRODUCT($Q$16:$Q$17,ED$16:ED$17) -> 1601.6 | EE7: =SUMPRODUCT($Q$16:$Q$17,EE$16:EE$17) -> 3952 | EF7: Parc dominé par tempo méca : robustesse, simplicité, adaptation aux usages intensifs. Electronique progresse mais reste minoritaire, freinée par contraintes maintenance/coût. | EG7: =SUMPRODUCT($Q$16:$Q$17,EG$16:EG$17) -> 1362.4 | EH7: =SUMPRODUCT($Q$16:$Q$17,EH$16:EH$17) -> 8981.5 | EI7: =SUMPRODUCT($Q$16:$Q$17,EI$16:EI$17) -> 2111.7 | EJ7: =SUMPRODUCT($Q$16:$Q$17,EJ$16:EJ$17) -> 3874.4 | EK7: Part temporisé électro. augmente légèrement => enjeux hygiène sans contact + maîtrise de conso. eau. Mécanique recule légèrement mais reste majoritaire => fiabilité en usage intensif. | EM7: =SUMPRODUCT($Q$16:$Q$17,EM$16:EM$17) -> 33774 | EN7: =SUMPRODUCT($Q$16:$Q$17,EN$16:EN$17) -> 23244 | EO7: =SUMPRODUCT($Q$16:$Q$17,EO$16:EO$17) -> 10062 | EP7: Parc WC repose surtout sur systèmes gravitaires, mécaniques, robustes, économiques, faciles à maintenir. Electronique secondaire mais présent dans lieux premium ou à forte exigence sanitaire. | EQ7: =SUMPRODUCT($Q$16:$Q$17,EQ$16:EQ$17) -> 27618 | ER7: =SUMPRODUCT($Q$16:$Q$17,ER$16:ER$17) -> 27013.2 | ES7: =SUMPRODUCT($Q$16:$Q$17,ES$16:ES$17) -> 13783.8 | ET7: Electronique gagne du terrain, surtout sur ERP récents-rénovés => exigences hygiène + automatisation => Progression faible : solutions méca conservent avantage coût/fiabilité. | EV7: =IFERROR(EY7/EX7,0) -> 0.81992162 | EW7: =IFERROR(EZ7/EX7,0) -> 0.18007838 | EX7: =EY7+EZ7 -> 514869.48 | EY7: =SUM(FB7,FE7,FH7,FK7) -> 422152.61 | EZ7: =SUM(FC7,FF7,FI7,FL7) -> 92716.861 | FA7: =SUM(FA9:FA17) -> 476551.75 | FB7: =SUM(FB9:FB17) -> 390194.47 | FC7: =SUM(FC9:FC17) -> 86357.279 | FD7: =SUM(FD9:FD17) -> 54838.454 | FE7: =SUMPRODUCT($Q$16:$Q$17,FE$16:FE$17) -> 1453.9034 | FF7: =SUMPRODUCT($Q$16:$Q$17,FF$16:FF$17) -> 226.72 | FG7: =SUMPRODUCT($Q$16:$Q$17,FG$16:FG$17) -> 7757.7818 | FH7: =SUMPRODUCT($Q$16:$Q$17,FH$16:FH$17) -> 6580.8834 | FI7: =SUMPRODUCT($Q$16:$Q$17,FI$16:FI$17) -> 1176.8984 | FJ7: =SUMPRODUCT($Q$16:$Q$17,FJ$16:FJ$17) -> 28879.319 | FK7: =SUMPRODUCT($Q$16:$Q$17,FK$16:FK$17) -> 23923.356 | FL7: =SUMPRODUCT($Q$16:$Q$17,FL$16:FL$17) -> 4955.9628 | FN7: Agrégat Pondéré | FO7: =IFERROR(SUMPRODUCT($Q$16:$Q$17,$AF$16:$AF$17,$FO$16:$FO$17)/SUMPRODUCT($Q$16:$Q$17,$AF$16:$AF$17),"") -> 0.060657692 | FP7: =IFERROR(SUMPRODUCT($Q$16:$Q$17,$AF$16:$AF$17,$FP$16:$FP$17)/SUMPRODUCT($Q$16:$Q$17,$AF$16:$AF$17),"") -> 0.82671538 | FQ7: Taux moyen pondéré France de matérialisation des travaux sur 2026-2030. | FS7: 3.19 | FT7: - | FU7: 3.97 | FV7: - | FW7: 2.24 | FX7: - | GF7: =HYPERLINK("https://www.ecologie.gouv.fr/eco-energie-tertiaire-eet","https://www.ecologie.gouv.fr/eco-energie-tertiaire-eet")&CHAR(10)&HYPERLINK("https://www.info.gouv.fr/actualite/segur-de-la-sante-de-nouveaux-investissements-pour-l-hopital","https://www.info.gouv.fr/actualite/segur-de-la-sante-de-nouveaux-investissements-pour-l-hopital")&CHAR(10)&HYPERLINK("https://www.cnsa.fr/budget-et-financement/financement-des-esms/investissement-immobilier","https://www.cnsa.fr/budget-et-financement/financement-des-esms/investissement-immobilier")&CHAR(10)&HYPERLINK("https://www.agencedusport.fr/plan-5000-equipements-generation-2024","https://www.agencedusport.fr/plan-5000-equipements-generation-2024")&CHAR(10)&HYPERLINK("https://www.france-services.gouv.fr/actualites/labellisation-nouvelles-maisons-france-services","https://www.france-services.gouv.fr/actualites/labellisation-nouvelles-maisons-france-services")&CHAR(10)&HYPERLINK("https://www.justice.gouv.fr/plan-15-000-places-prison","https://www.justice.gouv.fr/plan-15-000-places-prison")&CHAR(10)&HYPERLINK("https://www.defense.gouv.fr/ministere/politique-defense/loi-programmation-militaire-2024-2030","https://www.defense.gouv.fr/ministere/politique-defense/loi-programmation-militaire-2024-2030")&CHAR(10)&HYPERLINK("https://www.economie.gouv.fr/cedef/reindustrialisation-informations","https://www.economie.gouv.fr/cedef/reindustrialisation-informations")&CHAR(10)&HYPERLINK("https://presse.groupeadp.fr/proposition-cre2027-2034/","https://presse.groupeadp.fr/proposition-cre2027-2034/")&CHAR(10)&HYPERLINK("https://www.garesetconnexions.sncf/fr/qui-sommes-nous/notre-modele-economique","https://www.garesetconnexions.sncf/fr/qui-sommes-nous/notre-modele-economique") -> https://www.ecologie.gouv.fr/eco-energie-tertiaire-eet https://www.info.gouv.fr/actualite/segur-de-la-sante-de-nouveaux-investissements-pour-l-hopital https://www.cnsa.fr/budget-et-financement/financement-des-esms/investissement-immobilier https://www.agencedusport.fr/plan-5000-equipements-generation-2024 https://www.france-services.gouv.fr/actualites/labellisation-nouvelles-maisons-france-services https://www.justice.gouv.fr/plan-15-000-places-prison https://www.defense.gouv.fr/ministere/politique-defense/loi-programmation-militaire-2024-2030 https://www.economie.gouv.fr/cedef/reindustrialisation-informations https://presse.groupeadp.fr/proposition-cre2027-2034/ https://www.garesetconnexions.sncf/fr/qui-sommes-nous/notre-modele-economique | GH7: =SUM(GH9:GH17) -> 185836.81 | GI7: =SUM(GI9:GI17) -> 154462.69 | GJ7: =SUM(GJ9:GJ17) -> 31374.12 | GK7: =SUM(GK9:GK17) -> 168171.53 | GL7: =SUM(GL9:GL17) -> 133980.06 | GM7: =SUM(GM9:GM17) -> 34191.471 | GN7: =SUM(GN9:GN17) -> 99151.628 | GO7: =SUM(GO9:GO17) -> 81583.987 | ... GS7: =SUM(GS9:GS17) -> 3224.047 | GT7: =SUMPRODUCT($Q$16:$Q$17,GT$16:GT$17) -> 688.15111 | GU7: =SUMPRODUCT($Q$16:$Q$17,GU$16:GU$17) -> 597.46311 | GV7: =SUMPRODUCT($Q$16:$Q$17,GV$16:GV$17) -> 90.688 | GW7: =SUMPRODUCT($Q$16:$Q$17,GW$16:GW$17) -> 772.0294 | GX7: =SUMPRODUCT($Q$16:$Q$17,GX$16:GX$17) -> 665.471 | GY7: =SUMPRODUCT($Q$16:$Q$17,GY$16:GY$17) -> 106.5584 | GZ7: =SUMPRODUCT($Q$16:$Q$17,GZ$16:GZ$17) -> 220.44291 | HA7: =SUMPRODUCT($Q$16:$Q$17,HA$16:HA$17) -> 190.96931 | ... HW7: =SUMPRODUCT($Q$16:$Q$17,HW$16:HW$17) -> 1005.2918 | HY7: =SUM(HZ7:ID7) -> 1398497 | HZ7: =IFERROR(IO7*BE7,0)+IFERROR(IY7*BF7,0)+IFERROR(JI7*BG7,0)+IFERROR(JS7*BH7,0) -> 50401.462 | IA7: =IFERROR(IP7*BE7,0)+IFERROR(IZ7*BF7,0)+IFERROR(JJ7*BG7,0)+IFERROR(JT7*BH7,0) -> 555413.5 | IB7: =IFERROR(IQ7*BE7,0)+IFERROR(JA7*BF7,0)+IFERROR(JK7*BG7,0)+IFERROR(JU7*BH7,0) -> 674932.46 | IC7: =IFERROR(IR7*BE7,0)+IFERROR(JB7*BF7,0)+IFERROR(JL7*BG7,0)+IFERROR(JV7*BH7,0) -> 114374.5 | ID7: =IFERROR(IS7*BE7,0)+IFERROR(JC7*BF7,0)+IFERROR(JM7*BG7,0)+IFERROR(JW7*BH7,0) -> 3375.0808 | IE7: =SUM(IF7:IJ7) -> 422152.61 | IF7: =IFERROR(IT7*FB7,0)+IFERROR(JD7*FE7,0)+IFERROR(JN7*FH7,0)+IFERROR(JX7*FK7,0) -> 5979.7299 | IG7: =IFERROR(IU7*FB7,0)+IFERROR(JE7*FE7,0)+IFERROR(JO7*FH7,0)+IFERROR(JY7*FK7,0) -> 150099.05 | IH7: =IFERROR(IV7*FB7,0)+IFERROR(JF7*FE7,0)+IFERROR(JP7*FH7,0)+IFERROR(JZ7*FK7,0) -> 214559.12 | II7: =IFERROR(IW7*FB7,0)+IFERROR(JG7*FE7,0)+IFERROR(JQ7*FH7,0)+IFERROR(KA7*FK7,0) -> 47498.766 | IJ7: =IFERROR(IX7*FB7,0)+IFERROR(JH7*FE7,0)+IFERROR(JR7*FH7,0)+IFERROR(KB7*FK7,0) -> 4015.942 | IK7: 3.86 | IL7: Bonne | IO7: =SUMPRODUCT($BE$9:$BE$17,IO$9:IO$17)/SUM($BE$9:$BE$17) -> 0.033790102 | IP7: =SUMPRODUCT($BE$9:$BE$17,IP$9:IP$17)/SUM($BE$9:$BE$17) -> 0.39809399 | IQ7: =SUMPRODUCT($BE$9:$BE$17,IQ$9:IQ$17)/SUM($BE$9:$BE$17) -> 0.48806546 | IR7: =SUMPRODUCT($BE$9:$BE$17,IR$9:IR$17)/SUM($BE$9:$BE$17) -> 0.07845645 | IS7: =SUMPRODUCT($BE$9:$BE$17,IS$9:IS$17)/SUM($BE$9:$BE$17) -> 0.0015939967 | IT7: =SUMPRODUCT($FA$9:$FA$17,IT$9:IT$17)/SUM($FA$9:$FA$17) -> 0.012850347 | IU7: =SUMPRODUCT($FA$9:$FA$17,IU$9:IU$17)/SUM($FA$9:$FA$17) -> 0.36191729 | IV7: =SUMPRODUCT($FA$9:$FA$17,IV$9:IV$17)/SUM($FA$9:$FA$17) -> 0.51279103 | IW7: =SUMPRODUCT($FA$9:$FA$17,IW$9:IW$17)/SUM($FA$9:$FA$17) -> 0.10479162 | IX7: =SUMPRODUCT($FA$9:$FA$17,IX$9:IX$17)/SUM($FA$9:$FA$17) -> 0.0076497131 | IY7: 0.072 | IZ7: 0.3519 | JA7: 0.384 | JB7: 0.1679 | JC7: 0.0242 | JD7: 0.0355 | JE7: 0.2767 | JF7: 0.4095 | JG7: 0.2317 | JH7: 0.0466 | JI7: 0.1234 | JJ7: 0.4706 | JK7: 0.3199 | JL7: 0.0759 | JM7: 0.0102 | JN7: 0.056 | JO7: 0.3741 | JP7: 0.4166 | JQ7: 0.1327 | JR7: 0.0206 | JS7: 0.0574 | JT7: 0.3634 | JU7: 0.4197 | JV7: 0.144 | JW7: 0.0155 | JX7: 0.0228 | JY7: 0.2515 | JZ7: 0.4654 | KA7: 0.2257 | KB7: 0.0346 | KD7: ±4 pts | KE7: ±5 pts | KF7: 4.15 | KG7: Bonne | KH7: Agrégation volume × mix par sous-segment ; les gros gisements (bureaux, écoles, santé, sport, hôtels, transports) pèsent davantage dans le total que les niches. | KI7: Total France pondéré par volumes 2025 et ventes 2026-2030 ; forte fréquentation tire le standard, image/privé tire premium, contrainte sanitaire renforce surtout le milieu de gamme technique. | KJ7: Agrégation volume × ventes 2026-2030 ; le neuf et les rénovations lourdes tirent le mix vers l’moyen/premium, mais la rénovation majoritaire garde un centre de gravité basique/moyen.
J8: Evolution moyenne anuelle => | Q8: 0 = sous-catég. | S8: Variat° Annuelle en % => | T8: =(T7/S7)^(1/(T4-S4))-1 -> 0.0051637858 | U8: =(U7/T7)^(1/(U4-T4))-1 -> 0.0050338115 | V8: =(V7/U7)^(1/(V4-U4))-1 -> 0.0057193273 | W8: =W7/V7-1 -> 0.012048193 | X8: =X7/W7-1 -> 0.011904762 | Y8: =Y7/X7-1 -> 0.011764706 | Z8: =Z7/Y7-1 -> 0.011627907 | AA8: =AA7/Z7-1 -> 0.0038314176 | AB8: =AB7/AA7-1 -> 0.0045801527 | AC8: =AC7/AB7-1 -> 0.0083586626 | AD8: =AD7/AC7-1 -> 0.0067822155 | AE8: =AE7/AD7-1 -> 0.005988024 | AG8: =AG7/AF7-1 -> -0.98558257 | AH8: =AH7/AG7-1 -> 0.0073421439 | AI8: =AI7/AH7-1 -> 0.0072886297 | AJ8: =AJ7/AI7-1 -> 0.00723589 | AK8: =(AK7/AF7)^(1/(AK4-AF4))-1 -> 0.00030679071 | BH8: Variat° Annuelle en % => | BI8: =(BI7/BD7)^(1/(2030-2025))-1 -> 0.00069306945 | BJ8: =(BJ7/BE7)^(1/(2030-2025))-1 -> 0.00048000005 | BK8: =(BK7/BF7)^(1/(2030-2025))-1 -> 0.0031056499 | BL8: =(BL7/BG7)^(1/(2030-2025))-1 -> 0.003890686 | BM8: =(BM7/BH7)^(1/(2030-2025))-1 -> 0.0039490092 | DS8: =DS7/SUM(DS7:DU7) -> 0.45 | DT8: =DT7/SUM(DS7:DU7) -> 0.45 | DU8: =DU7/SUM(DS7:DU7) -> 0.1 | DV8: <= Split en % => | DW8: =DW7/SUM(DW7:DY7) -> 0.4 | DX8: =DX7/SUM(DW7:DY7) -> 0.47 | DY8: =DY7/SUM(DW7:DY7) -> 0.13 | EB8: =EB7/SUM(EB7:EE7) -> 0.10324675 | EC8: =EC7/SUM(EB7:EE7) -> 0.55 | ED8: =ED7/SUM(EB7:EE7) -> 0.1 | EE8: =EE7/SUM(EB7:EE7) -> 0.24675325 | EF8: <= Split en % => | EG8: =EG7/SUM(EG7:EJ7) -> 0.083429271 | EH8: =EH7/SUM(EG7:EJ7) -> 0.55 | EI8: =EI7/SUM(EG7:EJ7) -> 0.12931415 | EJ8: =EJ7/SUM(EG7:EJ7) -> 0.23725658 | EM8: =EM7/SUM(EL7:EO7) -> 0.50348837 | EN8: =EN7/SUM(EL7:EO7) -> 0.34651163 | EO8: =EO7/SUM(EL7:EO7) -> 0.15 | EP8: <= Split en % => | EQ8: =EQ7/SUM(EQ7:ES7) -> 0.4036834 | ER8: =ER7/SUM(EQ7:ES7) -> 0.39484324 | ES8: =ES7/SUM(EQ7:ES7) -> 0.20147336 | EX8: Split en % => | EY8: =EY7/EX7 -> 0.81992162 | EZ8: =EZ7/EX7 -> 0.18007838 | FB8: =FB7/FA7 -> 0.8187872 | FC8: =FC7/FA7 -> 0.1812128 | FE8: =FE7/FD7 -> 0.02651248 | FF8: =FF7/FD7 -> 0.0041343252 | FH8: =FH7/FG7 -> 0.84829447 | FI8: =FI7/FG7 -> 0.15170553 | FK8: =FK7/FJ7 -> 0.82839059 | FL8: =FL7/FJ7 -> 0.17160941 | GH8: Split en % => | GI8: =GI7/GH7 -> 0.83117381 | GJ8: =GJ7/GH7 -> 0.16882619 | GL8: =GL7/GK7 -> 0.79668692 | GM8: =GM7/GK7 -> 0.20331308 | GO8: =GO7/GN7 -> 0.82282045 | GP8: =GP7/GN7 -> 0.17717955 | GR8: =GR7/GQ7 -> 0.86217182 | GS8: =GS7/GQ7 -> 0.13782818 | GU8: =GU7/GT7 -> 0.86821499 | GV8: =GV7/GT7 -> 0.13178501 | GX8: =GX7/GW7 -> 0.86197624 | GY8: =GY7/GW7 -> 0.13802376 | HA8: =HA7/GZ7 -> 0.86629826 | HB8: =HB7/GZ7 -> 0.13370174 | HD8: =HD7/HC7 -> 0.87934458 | HE8: =HE7/HC7 -> 0.12065542 | HG8: =HG7/HF7 -> 0.83052373 | HH8: =HH7/HF7 -> 0.16947627 | HJ8: =HJ7/HI7 -> 0.85749882 | HK8: =HK7/HI7 -> 0.14250118 | HM8: =HM7/HL7 -> 0.86397878 | HN8: =HN7/HL7 -> 0.13602122 | HP8: =HP7/HO7 -> 0.84897404 | HQ8: =HQ7/HO7 -> 0.15102596 | HS8: =HS7/HR7 -> 0.79691071 | HT8: =HT7/HR7 -> 0.20308929 | HV8: =HV7/HU7 -> 0.83249713 | HW8: =HW7/HU7 -> 0.16750287 | HY8: Split en % => | HZ8: =HZ7/HY7 -> 0.036039736 | IA8: =IA7/HY7 -> 0.3971503 | IB8: =IB7/HY7 -> 0.48261273 | IC8: =IC7/HY7 -> 0.081783869 | ID8: =ID7/HY7 -> 0.0024133629 | IF8: =IF7/IE7 -> 0.014164853 | IG8: =IG7/IE7 -> 0.35555638 | IH8: =IH7/IE7 -> 0.50825013 | II8: =II7/IE7 -> 0.11251563 | IJ8: =IJ7/IE7 -> 0.0095130098 | IS8: Evolutions en Pts => | IT8: =(IT7-IO7)*100 -> -2.0939755 | IU8: =(IU7-IP7)*100 -> -3.6176703 | IV8: =(IV7-IQ7)*100 -> 2.4725568 | IW8: =(IW7-IR7)*100 -> 2.6335173 | IX8: =(IX7-IS7)*100 -> 0.60557164 | JC8: Evolutions en Pts => | JD8: =(JD7-IY7)*100 -> -3.65 | JE8: =(JE7-IZ7)*100 -> -7.52 | JF8: =(JF7-JA7)*100 -> 2.55 | JG8: =(JG7-JB7)*100 -> 6.38 | JH8: =(JH7-JC7)*100 -> 2.24 | JM8: Evolutions en Pts => | JN8: =(JN7-JI7)*100 -> -6.74 | JO8: =(JO7-JJ7)*100 -> -9.65 | JP8: =(JP7-JK7)*100 -> 9.67 | JQ8: =(JQ7-JL7)*100 -> 5.68 | JR8: =(JR7-JM7)*100 -> 1.04 | JW8: Evolutions en Pts => | JX8: =(JX7-JS7)*100 -> -3.46 | JY8: =(JY7-JT7)*100 -> -11.19 | JZ8: =(JZ7-JU7)*100 -> 4.57 | KA8: =(KA7-JV7)*100 -> 8.17 | KB8: =(KB7-JW7)*100 -> 1.91
