Workbook

Sheet Hypothèses - DuréeVie - ERP&Pdt
A1: Méthodologie de durée de vie réelle (parc installé 2025)
A2: Horizon de calcul des pièces à rénover | C2: 5 ans (2025-2030). Formule principale sur l’onglet principal : stock 2025 × min(1 ; 5 / durée de vie réelle).
A4: Code profil | B4: Libellé profil | C4: Usage / logique | D4: Lav M | E4: Lav TM | F4: Lav TE | G4: Lav Aut | H4: Dou M | I4: Dou TM | J4: Dou TE | K4: Uri Res | L4: Uri DM | M4: Uri DEI | N4: Uri DEC | O4: WC Res | P4: WC DM | Q4: WC DE | R4: Sources / éléments tangibles (URLs)
A5: P1 | B5: Petite enfance supervisée | C5: Faible vandalisme, forte supervision adulte et maintenance régulière, mais lavage des mains intensif. Renouvellement plutôt par campagne bâtiment qu’en urgence. | D5: 14 | E5: 13 | F5: 10 | G5: 12 | H5: 14 | I5: 13 | J5: 10 | K5: 13 | L5: 14 | M5: 10 | N5: 12 | O5: 15 | P5: 15 | Q5: 11 | R5: https://www.delabie.fr/nos-services/notre-expertise/nos-solutions/robinetterie-pour-lieux-publics | https://www.delabie.fr/nos-produits/robinetterie-pour-lieux-publics/robinet-de-lavabo-temporise/740500-robinet-de-lavabo-temporise-temposoft-2
A6: P2 | B6: Enseignement intensif sous contrainte budgétaire | C6: Pics interclasses, usage quotidien élevé, vandalisme modéré et budgets publics souvent lissés. Le temporisé et la chasse directe tiennent mieux que le manuel/réservoir en usage intensif. | D6: 12 | E6: 13 | F6: 9 | G6: 11 | H6: 12 | I6: 11 | J6: 8 | K6: 10 | L6: 13 | M6: 9 | N6: 11 | O6: 11 | P6: 13 | Q6: 10 | R6: https://www.delabie.fr/nos-services/notre-expertise/nos-solutions/robinetterie-pour-lieux-publics | https://www.renovation-bati-scolaire.fr/ressources/fonds-vert-2025
A7: P3 | B7: Campus tertiaire / enseignement supérieur | C7: Usage adulte, fréquentation soutenue mais moins agressive, rénovations périodiques de campus et obligations de mise à niveau tertiaire. | D7: 13 | E7: 14 | F7: 10 | G7: 12 | H7: 13 | I7: 12 | J7: 9 | K7: 11 | L7: 14 | M7: 10 | N7: 12 | O7: 12 | P7: 14 | Q7: 11 | R7: https://www.ecologie.gouv.fr/eco-energie-tertiaire-eet | https://www.delabie.fr/nos-services/notre-expertise/nos-solutions/robinetterie-pour-lieux-publics
A8: P4 | B8: Résidentiel éducatif / jeunesse | C8: Usage résidentiel ou semi-résidentiel, douches plus sollicitées, pics saisonniers mais moindre vandalisme que le scolaire de jour. | D8: 14 | E8: 13 | F8: 10 | G8: 12 | H8: 13 | I8: 12 | J8: 9 | K8: 12 | L8: 13 | M8: 9 | N8: 11 | O8: 14 | P8: 13 | Q8: 10 | R8: https://www.ecologie.gouv.fr/politiques-publiques/sante-construction-plomb-legionelle | https://www.delabie.fr/nos-services/notre-expertise/nos-solutions/robinetterie-pour-lieux-publics
A9: P5 | B9: Loisirs jeunesse / usage saisonnier | C9: Fréquentation par pics, usage parfois extérieur/saisonnier, surveillance variable et maintenance souvent concentrée hors saison. | D9: 13 | E9: 13 | F9: 9 | G9: 11 | H9: 12 | I9: 11 | J9: 8 | K9: 10 | L9: 12 | M9: 8 | N9: 10 | O9: 11 | P9: 12 | Q9: 9 | R9: https://www.ecologie.gouv.fr/politiques-publiques/sante-construction-plomb-legionelle | https://www.delabie.fr/nos-services/notre-expertise/nos-solutions/robinetterie-pour-lieux-publics
A10: P6 | B10: Santé hospitalière aiguë | C10: Forte exigence d’hygiène, prévention légionelles, nettoyage fréquent et remplacements préventifs liés aux travaux Ségur ou à la conformité sanitaire. | D10: 12 | E10: 11 | F10: 8 | G10: 10 | H10: 11 | I10: 10 | J10: 8 | K10: 10 | L10: 12 | M10: 8 | N10: 10 | O10: 12 | P10: 12 | Q10: 9 | R10: https://fides.sante.gouv.fr/soins-et-maladies/maladies/maladies-et-infections-respiratoires/article/prevention-de-la-legionellose-les-obligations-par-type-d-installation-et-d | https://igas.gouv.fr/pour-un-pilotage-renforce-des-investissements-immobiliers-des-etablissements-de-sante-consolider-lexpertise-et-la-maitrise-douvrage-hospitaliere-0 | https://www.delabie.fr/nos-services/notre-expertise/dossiers-thematiques/chasse-directe-la-reponse-adaptee-aux-problematiques-des-lieux-publics
A11: P7 | B11: Santé spécialisée / ambulatoire / médico-éducatif | C11: Contrainte hygiène maintenue mais fréquentation moins continue que l’hospitalier aigu ; maintenance régulière, renouvellement par lots lors de travaux ciblés. | D11: 12 | E11: 12 | F11: 9 | G11: 10 | H11: 12 | I11: 11 | J11: 8 | K11: 11 | L11: 12 | M11: 8 | N11: 10 | O11: 12 | P11: 12 | Q11: 9 | R11: https://fides.sante.gouv.fr/soins-et-maladies/maladies/maladies-et-infections-respiratoires/article/prevention-de-la-legionellose-les-obligations-par-type-d-installation-et-d | https://www.delabie.fr/nos-services/notre-expertise/nos-solutions/robinetterie-pour-lieux-publics
A12: P8 | B12: Médico-social résidentiel / seniors / handicap | C12: Forte part d’usage résidentiel ou en chambre, moindre vandalisme, mais entretien régulier pour limiter stagnation/tartre ; remplacement souvent en lots de chambres ou d’unités. | D12: 14 | E12: 13 | F12: 10 | G12: 12 | H12: 13 | I12: 12 | J12: 9 | K12: 13 | L12: 13 | M12: 9 | N12: 11 | O12: 15 | P12: 13 | Q12: 10 | R12: https://cpias-occitanie.fr/outils-cpias-occitanie/guide-legionelles-en-ehpad/ | https://fides.sante.gouv.fr/soins-et-maladies/maladies/maladies-et-infections-respiratoires/article/prevention-de-la-legionellose-les-obligations-par-type-d-installation-et-d | https://www.delabie.com/our-services/our-expertise/dossiers/direct-flush-designed-to-solve-the-problems-faced-by-public-places
A13: P9 | B13: Culture / conférence / exposition | C13: Usage public modéré à fort mais irrégulier, pics événementiels, budgets municipaux/intercommunaux et rénovation par campagnes plutôt que remplacement à la panne. | D13: 13 | E13: 13 | F13: 10 | G13: 12 | H13: 13 | I13: 12 | J13: 9 | K13: 11 | L13: 13 | M13: 9 | N13: 11 | O13: 12 | P13: 13 | Q13: 10 | R13: https://www.ecologie.gouv.fr/eco-energie-tertiaire-eet | https://www.delabie.fr/nos-services/notre-expertise/dossiers-thematiques/chasse-directe-la-reponse-adaptee-aux-problematiques-des-lieux-publics
A14: P10 | B14: Restauration / bars / nightlife / loisirs indoor | C14: Longues amplitudes, forte humidité, nettoyage agressif, image commerciale importante et vandalisme plus élevé en soirée/nuit. | D14: 10 | E14: 11 | F14: 8 | G14: 9 | H14: 11 | I14: 10 | J14: 8 | K14: 9 | L14: 11 | M14: 8 | N14: 9 | O14: 10 | P14: 11 | Q14: 9 | R14: https://www.delabie.fr/nos-services/notre-expertise/dossiers-thematiques/chasse-directe-la-reponse-adaptee-aux-problematiques-des-lieux-publics | https://www.cws.com/fr-LU/hygiene/centre-de-connaissances/sanitaires-anti-vandalisme
A15: P11 | B15: Commerce / transport / parkings / sanitaires publics très intensifs | C15: Très forte fréquentation, disponibilité immédiate requise, vandalisme et coûts d’exploitation élevés ; la temporisation mécanique et la chasse directe sont favorisées. | D15: 9 | E15: 11 | F15: 8 | G15: 9 | H15: 10 | I15: 10 | J15: 8 | K15: 8 | L15: 11 | M15: 8 | N15: 9 | O15: 9 | P15: 12 | Q15: 9 | R15: https://www.delabie.fr/nos-services/notre-expertise/dossiers-thematiques/chasse-directe-la-reponse-adaptee-aux-problematiques-des-lieux-publics | https://www.cws.com/fr-LU/hygiene/centre-de-connaissances/sanitaires-anti-vandalisme | https://www.delabie.fr/nos-produits/robinetterie-pour-lieux-publics/robinet-d-urinoir-automatique-et-temporise/479410-robinet-d-urinoir-automatique-tempomatic-4
A16: P12 | B16: Bureaux / administration / justice | C16: Usage tertiaire moyen, faible vandalisme, rénovations par lots tirées par l’immobilier tertiaire, l’accessibilité et la trajectoire Éco Énergie Tertiaire. | D16: 13 | E16: 13 | F16: 10 | G16: 12 | H16: 13 | I16: 12 | J16: 9 | K16: 11 | L16: 13 | M16: 9 | N16: 11 | O16: 12 | P16: 13 | Q16: 10 | R16: https://www.ecologie.gouv.fr/eco-energie-tertiaire-eet | https://www.delabie.fr/nos-services/notre-expertise/dossiers-thematiques/systeme-de-chasse-directe-wc-la-revolution-du-public
... A23: P19 | B23: Culte / associatif faible intensité | C23: Fréquentation faible à modérée, faible vandalisme, remplacement souvent différé pour raisons budgétaires ; équipements conservés plus longtemps. | D23: 15 | E23: 14 | F23: 10 | G23: 13 | H23: 14 | I23: 13 | J23: 9 | K23: 13 | L23: 14 | M23: 9 | N23: 12 | O23: 15 | P23: 14 | Q23: 10 | R23: https://www.ecologie.gouv.fr/eco-energie-tertiaire-eet | https://www.delabie.fr/nos-services/notre-expertise/nos-solutions/robinetterie-pour-lieux-publics
A26: Repères techniques utilisés
A27: R1 | B27: Robinetterie temporisée collective : durée de vie des piles 3 à 6 ans et mécanismes/électrovannes ≥ 500 000 manoeuvres. | C27: https://www.delabie.fr/nos-services/notre-expertise/nos-solutions/robinetterie-pour-lieux-publics
A28: R2 | B28: Lavabo temporisé : 3 l/min, temporisation ~7 s, garantie 30 ans. | C28: https://www.delabie.fr/nos-produits/robinetterie-pour-lieux-publics/robinet-de-lavabo-temporise/740500-robinet-de-lavabo-temporise-temposoft-2
A29: R3 | B29: Douche temporisée : ~15 s, mécanisme testé à plus de 500 000 manoeuvres. | C29: https://www.sider.biz/produit/robinet-temporise-delabie-m1-2.153713015
A30: R4 | B30: Urinoir temporisé : ~3 s, résistance > 500 000 manoeuvres. | C30: https://www.materiauxnet.com/robinet-d-urinoir-delabie-tempostop-alimentation-en-ligne.html
A31: R5 | B31: Urinoir électronique : rinçage périodique hygiénique 24h, mode affluence. | C31: https://www.delabie.fr/nos-produits/robinetterie-pour-lieux-publics/robinet-d-urinoir-automatique-et-temporise/479410-robinet-d-urinoir-automatique-tempomatic-4
A32: R6 | B32: WC chasse directe : conçue pour forte fréquentation, résistante au vandalisme, >500 000 manoeuvres, plus hygiénique que réservoir. | C32: https://www.delabie.fr/nos-services/notre-expertise/dossiers-thematiques/chasse-directe-la-reponse-adaptee-aux-problematiques-des-lieux-publics
A33: R7 | B33: Prévention légionelles : éviter stagnation, tartre et corrosion ; sujet critique dans santé/EHPAD. | C33: https://fides.sante.gouv.fr/soins-et-maladies/maladies/maladies-et-infections-respiratoires/article/prevention-de-la-legionellose-les-obligations-par-type-d-installation-et-d
A34: R8 | B34: Éco Énergie Tertiaire : -40 % d’énergie finale en 2030 pour le tertiaire > 1 000 m² ; favorise les rénovations par lots. | C34: https://www.ecologie.gouv.fr/eco-energie-tertiaire-eet
A35: R9 | B35: Sport : 182 700 équipements sportifs, gymnases et salles en zones urbaines ; occupation parfois très élevée. | C35: https://www.insee.fr/fr/statistiques/8376522
A36: R10 | B36: Hôpital : plan Ségur 7,5 Md€ pour moderniser le patrimoine hospitalier, mise en oeuvre cependant décalée. | C36: https://igas.gouv.fr/pour-un-pilotage-renforce-des-investissements-immobiliers-des-etablissements-de-sante-consolider-lexpertise-et-la-maitrise-douvrage-hospitaliere-0
A37: R11 | B37: Prisons : plan 15 000 places, parc ancien et fortement sollicité ; renouvellement partiel par nouveaux établissements d’ici 2027. | C37: https://www.justice.gouv.fr/plan-15-000-places-prison
A38: R12 | B38: Hôtels : rénovations typiquement par campagnes, souvent 7 à 10 ans pour maintenir le standard ; exemples de refresh à 20 ans quand l’asset reste fonctionnel. | C38: https://conceptrenodeco.fr/guides/renovation-hotel-moderniser-chambres-espaces/ | https://baudet-sa.com/detail-realisation/ibis-munster

Sheet Split Neuf-Réno selon CHAT
B2: Q1 | C2: Tout en occultant toutes les recherches précédentes réalisées sur le sujet ... peux-tu me dire, via d'autres sources, en France, sur la robinetterie sanitaire collective (lavabos + urinoirs + douche + WC), pour les ERP uniquement, quel serait en volume de pièces, le % consacré à la vente neuve et quel % serait consacré à la rénovation, sur la période 2025-2030, en tenant compte aussi de tous les facteurs endogènes et exogènes identifiés (notamment dynamique économique, dynamique de la construction, dynamique du marché de la robinetterie, impact de la situation internationale, finances puliques, politiques publiques, investissements privés, programme de relance nationaux, écart entre intention et réalisation, ou tout autre élément impactant l'activité) . Merci de me livrer un niveau de fiabilité de ta réponse, ta méthodologie et tes sources.
C4: Je repars de zéro et je vais construire une estimation indépendante, en m’appuyant cette fois sur des sources publiques/sectorielles externes et une modélisation explicite du marché ERP.
C6: Je tiens la structure du modèle. Le cœur de la réponse va reposer sur un point simple : en ERP, le volume neuf est mécaniquement limité par les mises en chantier annuelles, alors que la rénovation est tirée par un parc existant immense, par les obligations de rénovation tertiaire et par les programmes écoles/hôpitaux/bâtiments publics.
C8: Thought for 8m 36s
C10: Oui. En repartant indépendamment des échanges précédents et en m’appuyant sur des sources externes publiques/sectorielles, mon estimation centrale pour la robinetterie sanitaire collective en ERP en France — périmètre lavabos + urinoirs + douches + WC, en volume de pièces, hors logement — est la suivante :
C12: Année | D12: Volume total estimé (pièces) | E12: Neuf | F12: Rénovation
C13: 2025 | D13: 565000 | E13: 110 000 (20 %) | F13: 455 000 (80 %)
C14: 2026 | D14: 570000 | E14: 115 000 (20 %) | F14: 455 000 (80 %)
C15: 2027 | D15: 585000 | E15: 120 000 (21 %) | F15: 465 000 (79 %)
C16: 2028 | D16: 600000 | E16: 128 000 (21 %) | F16: 472 000 (79 %)
C17: 2029 | D17: 615000 | E17: 135 000 (22 %) | F17: 480 000 (78 %)
C18: 2030 | D18: 630000 | E18: 142 000 (23 %) | F18: 488 000 (77 %)
C20: Ma lecture synthétique est donc : sur 2025-2030, le marché ERP restera très majoritairement un marché de rénovation, autour de 77 % à 80 % des volumes, tandis que le neuf représenterait 20 % à 23 % selon les années. Cette domination de la rénovation est cohérente avec la taille du parc tertiaire existant, les obligations réglementaires de réduction de consommation dans l’existant, et le fait que la construction neuve non résidentielle reste nettement plus petite que le stock en exploitation.
C22: Ce qui me fait pencher vers 80/20 plutôt que 50/50
C24: Le point décisif est le poids du parc existant. L’ADEME estime la surface tertiaire chauffée à 976 millions de m² en 2023, et le Cerema estime qu’environ 740 millions de m² de locaux tertiaires de métropole sont déjà dans le champ du dispositif Éco Énergie Tertiaire pour les surfaces de plus de 1 000 m². En parallèle, le cahier 2026 du Fonds vert rappelle un parc tertiaire d’environ 1 milliard de m², dont plus du tiers pour les bâtiments publics de l’État et des collectivités, et indique que les collectivités détiennent à elles seules plus de 225 000 bâtiments pour 280 millions de m². Ce stock immense crée mécaniquement un volant de remplacement et de rénovation très supérieur à ce que peut générer le seul flux annuel de bâtiments neufs.
C26: À l’inverse, le neuf part d’un flux plus étroit. Sur les douze mois allant de février 2025 à janvier 2026, les mises en chantier de locaux non résidentiels atteignent 21,0 millions de m², en hausse de 2,8 %, mais les autorisations baissent encore légèrement à 37,2 millions de m² (-1,9 %). La FFB souligne en outre que le non-résidentiel neuf a encore reculé de 6,6 % en volume en 2025 après -4,1 % en 2024, même si les surfaces commencées ont montré une inflexion positive en 2025. Autrement dit : le neuf cesse de se dégrader autant qu’en 2024, mais il ne redevient pas le moteur principal du marché.
C28: Les facteurs qui soutiennent la rénovation ERP jusqu’en 2030
C30: Le principal moteur structurel est réglementaire : le dispositif Éco Énergie Tertiaire impose pour les bâtiments concernés une baisse de consommation d’énergie de -40 % en 2030, -50 % en 2040 et -60 % en 2050. Le cahier 2026 du Fonds vert rappelle aussi que la directive européenne sur l’efficacité énergétique impose une rénovation à haut niveau de performance d’au moins 3 % des surfaces des bâtiments publics de plus de 250 m² chauffés ou refroidis, ainsi qu’une baisse annuelle de 1,9 % de la consommation d’énergie des organismes publics. Même si la robinetterie n’est pas le premier poste d’investissement d’une rénovation énergétique, elle entre souvent dans les lots “sanitaires / eau / confort d’été / mise en conformité / modernisation”. Le Fonds vert rend d’ailleurs explicitement éligibles les équipements permettant de réduire la consommation d’eau.
C32: Le deuxième moteur est la massification de programmes ciblés sur les ERP publics. Côté scolaire, la Banque des Territoires indique environ 53 000 établissements scolaires publics, 130 millions de m² de surface et un programme EduRénov visant 10 000 projets d’ici 2027, avec 2 Md€ de prêts et 50 M€ d’ingénierie. En juillet 2025, Localtis indiquait déjà 5 000 chantiers engagés, et la ministre évoquait 2 Md€ supplémentaires. Côté santé, le Ségur représente 19 Md€ d’investissement jusqu’en 2030, dont une part majeure pour les établissements de santé. Côté justice, le ministère a aussi lancé des opérations de rénovation énergétique sur des tribunaux, centres de détention et autres sites. Tout cela alimente un flux de rénovation sanitaire dans des ERP très équipés en lavabos, WC, urinoirs et douches.
C34: Les facteurs qui freinent le marché
C36: Je ne vois pas un scénario de forte accélération linéaire, parce que plusieurs freins sont réels. La FFB signale une activité d’entretien-amélioration en recul, avec un non-résidentiel à -0,6 % entre T3 2024 et T3 2025, et même une légère érosion de la rénovation énergétique non résidentielle. La Banque des Territoires note un contexte budgétaire tendu pour les collectivités, une baisse de certaines aides et surtout un écart important entre étude et réalisation : selon Actee/Banque des Territoires, près de 50 % des projets s’arrêtent entre l’étude technique et la réalisation. Côté santé, le ministère évoque en 2025 un déficit estimé à 2,9 Md€ fin 2024 pour les établissements publics de santé, ce qui peut ralentir ou phaser certains investissements hors opérations déjà financées.
C38: Le contexte macro ne pousse pas non plus à un emballement. En mars 2026, la Banque de France prévoit une croissance du PIB français de 0,9 % en 2026, puis 0,8 % en 2027 avant 1,2 % en 2028, en soulignant que la hausse des prix de l’énergie et la détérioration du contexte géopolitique pèseraient sur l’activité et l’investissement des entreprises. La Banque mondiale anticipe de son côté des prix des métaux de base en hausse de 3 % en 2025, globalement stables en 2026, puis autour de +2 % en 2027. Enfin, l’indice Insee des prix de production de la robinetterie d’équipement du bâtiment est passé de 100 en 2021 à 120,7 en février 2026, ce qui signifie que la pression prix a déjà été forte depuis 2021, même si le rythme semble désormais plus calme. Cela tend à soutenir la valeur, mais à limiter le volume si les budgets chantier sont serrés.
C40: Ma méthodologie
C42: Je n’ai pas trouvé de série publique prête à l’emploi donnant directement le nombre de pièces de robinetterie sanitaire collective ERP vendues en France, ni leur ventilation neuf/rénovation. Les chiffres ci-dessus sont donc modélisés. Les statistiques publiques consultées décrivent surtout le parc tertiaire, la construction neuve non résidentielle, les programmes de rénovation et les prix de la robinetterie, pas ce sous-segment précis. La robinetterie sanitaire représente par ailleurs près de la moitié de la production commercialisée en valeur de la robinetterie de bâtiment, ce qui confirme l’importance du segment, mais pas son split ERP/neuf/réno.
... C68: Je peux aussi vous livrer une version plus “cabinet de conseil”, avec scénario bas / central / haut, ou un découpage par type de pièce : lavabos, urinoirs, douches, WC.

Sheet Chat avec Chat
B2: Q1 | C2: En France, en robinetterie collective quelle proportion du parc existant entre mitigeur, robinetterie électronique et robinetterie mécanique temporisée ? ... aussi pour les années 2026-2030, chaque année, quelle proportion entre chaque type de robinet - et pourquoi ? ... beaucoup de différence entre parc existant et ventes 2026-2030 ?
C4: Je vais chercher des sources de marché et des repères techniques français/européens, puis distinguer clairement parc installé et ventes neuves. Sur ce sujet, il est probable qu’on doive raisonner par estimation documentée plutôt que par statistique officielle unique.
C6: J’ai les principaux moteurs de fond : hygiène/sans contact, économie d’eau, maîtrise du risque sanitaire et maintenance/coût total. Je vais maintenant transformer ça en une estimation chiffrée cohérente, en séparant bien le parc installé des ventes annuelles.
C8: Réflexion durant 2m 29s
C10: Oui, mais il faut poser un cadre clair : il n’existe pas, à ma connaissance, de statistique publique française donnant la répartition nationale exacte du parc de robinetterie collective entre mitigeur, électronique et mécanique temporisée. Donc ce qui suit est une estimation de travail pour la robinetterie de lavabo / lave-mains en lieux collectifs (ERP, tertiaire, enseignement, santé, sport, transport), construite à partir des offres réellement dominantes du marché pro, des contraintes d’hygiène et de gestion de l’eau, et du rythme de renouvellement du parc.
C12: Ma lecture du parc existant 2026 en France est la suivante :
C14: robinetterie mécanique temporisée : ~54 %
C15: mitigeur “classique” manuel : ~32 %
C16: robinetterie électronique : ~14 %
C18: C’est cohérent avec un parc historiquement tiré par la temporisation mécanique dans les sanitaires à fort passage, parce qu’elle reste robuste, simple, économique et pensée pour l’usage intensif ; par exemple, les modèles temporisés pro affichent typiquement 3 l/min, ~15 s d’écoulement et jusqu’à 500 000 manœuvres. Le mitigeur manuel reste encore très présent dans les zones moins intensives, les bureaux, les locaux du personnel et une partie du parc ancien. L’électronique progresse, mais part d’un parc plus récent.
C20: Pour les ventes 2026, j’estimerais plutôt :
C22: mécanique temporisée : ~47 %
C23: électronique : ~33 %
... C28: Ma projection des ventes annuelles pour 2026-2030 serait :
C30: Année | D30: Mitigeur manuel | E30: Électronique | F30: Mécanique temporisée
C31: 2026 | D31: 0.2 | E31: 0.33 | F31: 0.47
C32: 2027 | D32: 0.19 | E32: 0.35 | F32: 0.46
C33: 2028 | D33: 0.18 | E33: 0.37 | F33: 0.45
C34: 2029 | D34: 0.17 | E34: 0.39 | F34: 0.44
C35: 2030 | D35: 0.16 | E35: 0.41 | F35: 0.43
C37: L’idée derrière cette courbe est simple : la temporisée mécanique reste très forte car elle garde un avantage de coût d’achat, de simplicité de maintenance et de résistance au vandalisme / usage intensif ; l’électronique gagne du terrain tous les ans grâce à l’hygiène sans contact, à la baisse des consommations d’eau et aux exigences de maîtrise sanitaire ; le mitigeur manuel recule dans les sanitaires collectifs à fort passage, mais ne disparaît pas car il garde des positions dans les bureaux, locaux de service et petites rénovations sous contrainte budgétaire.
C39: La projection du parc installé évolue forcément plus lentement. J’estimerais :
C41: Année | D41: Mitigeur manuel | E41: Électronique | F41: Mécanique temporisée
C42: 2026 | D42: 0.32 | E42: 0.14 | F42: 0.54
C43: 2027 | D43: 0.31 | E43: 0.15 | F43: 0.54
C44: 2028 | D44: 0.3 | E44: 0.17 | F44: 0.53
C45: 2029 | D45: 0.29 | E45: 0.18 | F45: 0.53
C46: 2030 | D46: 0.28 | E46: 0.2 | F46: 0.52
C48: Donc en 2030, même avec des ventes déjà très favorables à l’électronique, le parc resterait encore majoritairement temporisé mécanique, parce que la robinetterie collective se renouvelle lentement, souvent au fil des opérations de maintenance lourde, de réhabilitation sanitaire ou de remise en conformité, et non en remplacement massif annuel. La dynamique du non-résidentiel en France s’améliore un peu, mais on n’est pas dans un scénario de vague de reconstruction capable de retourner très vite le parc ; le Trésor signalait récemment une reprise portée par le non-résidentiel, tout en indiquant que l’investissement public ralentirait, et les données de construction de locaux montraient en 2025 une hausse modérée des autorisations, pas un boom.
C50: Sur votre question “beaucoup de différence entre parc existant et ventes ?”, ma réponse est oui, assez nettement. En 2026, dans cette estimation, l’électronique représente ~14 % du parc mais ~33 % des ventes. À l’inverse, le mitigeur manuel ferait encore ~32 % du parc mais seulement ~20 % des ventes. La temporisée mécanique, elle, reste forte des deux côtés : ~54 % du parc et ~47 % des ventes. C’est typiquement le profil d’un marché de remplacement où la nouvelle demande bascule plus vite que le stock installé.
C53: Pourquoi cette bascule se fait-elle ainsi ?
C55: D’abord, l’hygiène. Les fabricants et distributeurs pro poussent clairement le sans-contact pour les ERP et les établissements de soins ; Delabie met en avant la suppression du contact manuel, et les modèles électroniques récents intègrent souvent des fonctions de rinçage périodique utiles contre la stagnation. En parallèle, les obligations de gestion de la qualité de l’eau se renforcent, avec les plans de gestion de la sécurité sanitaire de l’eau et la vigilance sur les légionelles dans les ERP et établissements de santé.
C57: Ensuite, l’eau et l’énergie. Dans un sanitaire collectif, passer d’un robinet manuel “laissé ouvert” à une solution temporisée ou électronique à faible débit abaisse fortement les consommations. Les acteurs du marché mettent en avant des débits préréglés bas et, pour le sans-contact, des économies très élevées sur le lavage des mains. Cela pousse les cahiers des charges vers le temporisé et l’électronique, surtout en rénovation tertiaire.
C59: Enfin, le coût total. La temporisée mécanique garde un très bon rapport coût / robustesse / maintenance, donc elle reste souvent le choix rationnel dans les écoles, gymnases, équipements sportifs ou sanitaires publics très sollicités. L’électronique progresse surtout là où l’hygiène, l’image, le confort d’usage ou la gestion technique du bâtiment justifient le surcoût : santé, tertiaire premium, transport, aéroports, grands ERP récents.
C61: Mon point de vigilance : si vous élargissez la définition en intégrant beaucoup de bureaux internes, cuisines, locaux techniques ou hébergement, la part du mitigeur manuel remonte un peu. À l’inverse, si vous ciblez surtout sanitaires publics à fort trafic ou santé, la part de l’électronique dans les ventes peut être 5 à 10 points plus haute que mon scénario central.
C63: Pour un usage de modélisation, je vous conseillerais donc de retenir ce scénario central France 2026 :
C65: parc existant : manuel 32 % / électronique 14 % / temporisé mécanique 54 %
C66: ventes 2026 : manuel 20 % / électronique 33 % / temporisé mécanique 47 %
C67: ventes 2030 : manuel 16 % / électronique 41 % / temporisé mécanique 43 %
C69: Et la conclusion de fond est : oui, il y a une vraie différence entre parc et ventes ; l’électronique surperforme fortement en ventes, mais le parc reste dominé par la temporisation mécanique jusqu’en 2030.
...

Sheet Re-Challenge Data
B2: ERP | C2: 1 | D2: En France, Peux-tu me dire le nombre d'ERP comptabilisé. Combien d'étabilssements dans le Parc existant 2025.
E4: Oui — si tu parles bien des ERP = établissements recevant du public, le chiffre officiel récent utilisé par l’État pour la France est d’environ 2 millions d’ERP. La page gouvernementale mise à jour en février 2025 indique explicitement que « quelque 2 millions d’ERP sont aujourd’hui recensés en France ».
E6: Donc, pour le parc existant 2025, la bonne réponse est :
E8: ≈ 2 000 000 d’établissements (ERP) en France.
E10: Point utile : dans le dossier de presse gouvernemental de février 2025, l’État rappelle aussi qu’il reste 900 000 ERP non engagés dans une démarche d’accessibilité, ce qui confirme qu’on parle bien d’un parc national très proche de 2 millions d’établissements.
E12: Je n’ai pas trouvé, dans les sources officielles consultées, un total 2025 plus précis à l’unité que cet ordre de grandeur officiel. Si tu veux, je peux te donner ensuite une formulation prête à coller dans une note ou un slide.
C15: 2 | D15: Et parmi ces ERP, combien doivent compter des sanitaires (endroits où on trouve lavabo, douche, urinoirs, WC) ?
E17: Pas avec un chiffre national fiable à ce stade.
E19: La raison est que la règle n’est pas “tous les ERP doivent avoir des sanitaires ouverts au public”. Pour l’accessibilité, le texte dit : “chaque niveau accessible, lorsque des sanitaires y sont prévus pour le public” doit comporter au moins un WC adapté avec lavabo accessible. Autrement dit, l’obligation d’accessibilité porte sur les sanitaires s’ils existent pour le public ; elle ne dit pas que tous les ERP doivent forcément en proposer au public. Le guide ministériel ajoute que la mise à disposition de sanitaires est une obligation pour les cafés-restaurants et pour d’autres établissements, mais pas de façon générale pour l’ensemble des ERP.
E21: En revanche, pour le personnel, le Code du travail est beaucoup plus large : l’employeur doit mettre à disposition des travailleurs des lavabos, des cabinets d’aisance et, le cas échéant, des douches. Il fixe aussi des seuils minimaux, notamment 1 lavabo pour 10 travailleurs, et au moins 1 WC + 1 urinoir pour 20 hommes et 2 WC pour 20 femmes.
E23: Donc, la réponse la plus juste est la suivante : sur les ≈ 2 millions d’ERP recensés en France, il n’existe pas, dans les sources publiques officielles que j’ai trouvées, de nombre national publié disant combien “doivent compter des sanitaires”. Pour les sanitaires ouverts au public, ce sous-ensemble dépend du type d’activité et de la configuration de l’établissement. Pour les sanitaires dans l’établissement au sens large, il faut en plus savoir si l’ERP emploie des travailleurs. Les données ouvertes d’Acceslibre décrivent des champs d’accessibilité, y compris sur les toilettes, mais elles sont alimentées pour les collectivités renseignées et via des contributions volontaires ; ce n’est pas présenté comme un décompte national exhaustif de tous les ERP tenus d’avoir des sanitaires.
E25: En pratique :
E27: si tu parles des sanitaires ouverts au public : je ne peux pas te donner un nombre France 2025 sérieux à partir d’une source officielle unique ;
E28: si tu parles des sanitaires présents dans l’établissement, y compris pour le personnel : cela concerne probablement une très grande partie des ERP avec salariés, mais là encore je n’ai pas trouvé de total national consolidé.
E30: Je peux te faire maintenant une estimation argumentée du volume d’ERP concernés, en séparant sanitaires public et sanitaires personnel.
C33: 3 | D33: Faire maintenant une estimation argumentée du volume d’ERP concernés, en séparant sanitaires public et sanitaires personnel.
E35: Oui. En prenant comme base le parc 2025 d’environ 2,0 millions d’ERP en France, mon estimation raisonnable est la suivante : sanitaires ouverts au public : 0,5 à 0,8 million d’ERP ; sanitaires pour le personnel : 1,3 à 1,6 million d’ERP. Le point central que je retiendrais est ~650 000 ERP pour le public et ~1 450 000 ERP pour le personnel.
E37: Je précise l’hypothèse : ici, je parle d’ERP ayant au moins un local sanitaire au sens large, donc typiquement WC + lavabo, pas forcément une douche ni un urinoir. C’est important, car les douches ne sont exigées que dans certains cas pour le personnel, et côté public la réglementation vise aussi des établissements particuliers comportant des douches, de l’hébergement, des espaces d’essayage, etc.
E39: Pour les sanitaires ouverts au public, la règle juridique de base n’est pas “tous les ERP doivent en avoir”. Le texte d’accessibilité dit que chaque niveau accessible, lorsque des sanitaires sont prévus pour le public, doit comporter au moins un WC adapté avec lavabo accessible. Autrement dit, l’obligation porte sur l’accessibilité des sanitaires publics s’ils existent, pas sur leur présence universelle dans les 2 millions d’ERP.
E41: Ensuite, il faut regarder la composition probable du parc. Les sources gouvernementales prennent comme exemples d’ERP des lieux très variés, allant de la boulangerie, du coiffeur, du tabac ou de la pharmacie jusqu’aux écoles, établissements de santé et lieux culturels. Or, dans les petits ERP de proximité — très souvent de 5e catégorie — les sanitaires ouverts au public ne sont pas systématiques. Le Sénat rappelle d’ailleurs que, parmi les 900 000 ERP encore hors démarche d’accessibilité, près de 90 % relèvent de la 5e catégorie, ce qui confirme le poids des petits établissements dans le parc.
E43: À l’inverse, certains groupes d’ERP ont très probablement des sanitaires publics dans la grande majorité des cas : cafés, bars, restaurants, hôtels et hébergements, établissements de santé, écoles, équipements sportifs, lieux culturels, certaines gares et de nombreuses administrations recevant du public de façon prolongée. Pour les cafés et bars, la DGCCRF précise par exemple que l’exploitant peut refuser l’accès aux toilettes aux personnes qui ne consomment pas, ce qui montre bien que les toilettes font partie du service attendu pour la clientèle.
E45: À partir de là, mon inférence est que la part des ERP avec sanitaires ouverts au public est vraisemblablement bien inférieure à la moitié, mais nettement au-dessus d’un noyau trop restrictif comme les seuls restaurants/hôtels/écoles/hôpitaux. La fourchette la plus crédible me paraît être 25 % à 40 % du parc ERP, soit 500 000 à 800 000 ERP, avec un point central autour de 650 000. C’est une estimation de structure, pas un décompte officiel publié.
E47: Pour les sanitaires du personnel, la logique est différente. Le Code du travail impose à l’employeur de mettre à disposition des travailleurs des lavabos, des cabinets d’aisance et, le cas échéant, des douches. Il fixe aussi des minima, notamment 1 lavabo pour 10 travailleurs au plus et, pour les WC, 1 cabinet + 1 urinoir pour 20 hommes et 2 cabinets pour 20 femmes. Donc, dès qu’un ERP emploie du personnel, l’existence d’un sanitaire pour les travailleurs devient la situation normale.
E49: Le meilleur point d’appui statistique que j’ai trouvé est l’Insee : fin 2024, la France compte 2 411 570 établissements avec activité salariée dans l’année, dont 1 594 079 dans la sphère présentielle, c’est-à-dire les activités tournées vers la population présente sur le territoire. Comme le parc ERP est de l’ordre de 2 millions et qu’il comprend aussi beaucoup de petits établissements sans salarié ou avec uniquement un exploitant indépendant, on n’est pas à 2 millions d’ERP ayant une obligation “personnel” au sens du Code du travail. Mais on est clairement sur une majorité importante du parc.
E51: Mon estimation pour les sanitaires personnel est donc 65 % à 80 % du parc ERP, soit 1,3 à 1,6 million d’ERP, avec un point central autour de 1,45 million. Là encore, c’est une approximation argumentée : elle colle mieux aux ordres de grandeur Insee qu’une hypothèse trop basse, mais elle évite aussi de supposer à tort que quasiment tous les ERP ont du personnel salarié permanent.
E53: En résumé, sur ~2,0 millions d’ERP en France, je retiendrais :
E54: ~650 000 ERP avec sanitaires ouverts au public
E55: ~1 450 000 ERP avec sanitaires pour le personnel
C58: 4 | D58: J'ai réalisé un comptage fin ... Mon total est loin de ton compte ... Quels ERP mentionnés sont alors sous-évalués ? Quels ERP aurais-je pu oublier dans la liste (je pense au wagon de train, WC dans les avions, Douches à trouver sur les plages, autres ???). Peux-tu me mettre à la suite de la liste ces ERP Sous-Segment ? Merci de retrouver et de compléter le Segment Principal et la Catégorie chapeau et de compléter les lignes suivantes du tableau. Comment expliques-tu la différence entre ce que je trouve et ton chiffre ?
E60: Je vais ouvrir ton fichier Excel, repérer les lignes à compléter, puis comparer ta logique de comptage avec le périmètre “ERP” officiel pour expliquer l’écart.
E62: J’ai trouvé l’écart principal : ton fichier additionne aujourd’hui environ 720 000 unités, alors que le parc ERP national de référence est autour de 2 millions. L’écart vient surtout d’un périmètre très “équipements / institutions / grands sites”, avec probablement une forte sous-couverture des petits commerces et services de proximité.
E64: J’ai identifié les familles à ajouter et je les injecte dans le fichier, avec un second onglet qui explique l’écart et isole les faux “oubliés” qui ne sont en fait pas des ERP stricts.
E66: J’y ai ajouté une vingtaine de sous-segments probables manquants, et un onglet “Analyse écart”. Le total du fichier passe de 739 966 à 1 349 749 après ces ajouts de travail. Les plus gros angles morts que j’ai ajoutés sont surtout :
E68: petits commerces de proximité : boulangeries, boucheries, épiceries/supérettes, pharmacies, coiffure, beauté, opticiens, tabac, habillement, etc. ;
E69: santé ambulatoire : cabinets médicaux, dentaires, paramédicaux, laboratoires, imagerie ;
E70: services de proximité : agences bancaires, assurances, immobilier, réseau postal.
E72: Pourquoi l’écart avec le chiffre national reste important : le chiffre officiel d’environ 2 millions d’ERP vise un parc très large de bâtiments, locaux et enceintes recevant du public, avec un poids très fort des petits ERP de 5e catégorie très diffus dans le tissu de proximité. Ton fichier, lui, ressemblait davantage à un inventaire d’équipements, institutions et grands sites, donc il sous-comptait mécaniquement le “long tail” des petits commerces et cabinets.
E74: Sur tes exemples :
E76: wagons de train, WC dans les avions, bus / cars / tram / métro / RER : je les ai ajoutés dans le tableau, mais en Hors ERP avec 0 en comptage ERP. La raison est qu’ils relèvent du matériel roulant et de l’accessibilité des transports, encadrés par le code des transports, pas du parc ERP bâti.
E77: blocs sanitaires fixes de plage / front de mer : je les ai rangés en cas limite / mixte. Ils peuvent relever du domaine public, d’un équipement balnéaire ou d’un établissement support ; donc ce n’est pas une bonne idée de les ajouter en masse sans contrôle local, au risque de faire du double compte.
...

Sheet Détail Recherche - Nbre ERP
B2: 1 | C2: Enfance, enseignement et jeunesse | D2: Enfance / jeunesse | E2: Centres de loisirs sans hébergement | G2: Oui — en ordre de grandeur, je vous proposerais ceci pour la France entière, en parlant des ALSH / centres aérés / centres de loisirs sans hébergement :
G4: Année | H4: Estimation d’ordre de grandeur
G5: 2000 | H5: ≈ 12 000
G6: 2010 | H6: ≈ 20 000
G7: 2020 | H7: ≈ 32 000
G8: 2025 | H8: ≈ 32 000
G9: 2030 (prévision centrale) | H9: ≈ 32 000
G11: Avec une lecture un peu plus prudente :
G13: 2000 : 10 000 à 15 000
G14: 2010 : 18 000 à 22 000
G15: 2020 : environ 32 000
G16: 2025 : environ 32 000
G17: 2030 : 30 000 à 34 000, centre de fourchette ≈ 32 000
G19: Pourquoi cette estimation tient la route :
G21: En base récente, l’INJEP donne 32 000 lieux d’accueil en 2020-2021 pour les accueils de loisirs, et encore 32 000 lieux d’accueil en 2024-2025. Cela suggère un plateau national autour de 32 000 depuis le début des années 2020.
G23: Pour remonter dans le temps, on a un très bon repère sur le périscolaire : en 2015-2016, l’INJEP indique 28 600 lieux d’accueil périscolaire. Et un article de synthèse reprenant l’étude INJEP précise qu’en 2014-2015 on était à 23 200 lieux, contre environ 18 000 en 2012-2013, ce dernier chiffre étant déductible des 900 000 places pour un nombre moyen de 50 places par structure.
G25: Du coup, pour 2010, un ordre de grandeur autour de 20 000 est cohérent : on est avant l’explosion liée à la réforme des rythmes éducatifs de 2013-2015, mais déjà dans une phase de montée en charge engagée entre 2008 et 2013.
G27: Pour 2000, je serais plus prudent : je n’ai pas trouvé de série publique homogène donnant un chiffre national directement comparable. En revanche, une étude sur le milieu rural indique que la moitié des accueils observés ont été créés après 2000 et que la croissance s’est accélérée entre 2000 et 2010, ce qui va bien dans le sens d’un parc nettement plus faible en 2000 qu’en 2010 et très inférieur au niveau actuel. D’où ma fourchette 10 000 à 15 000, avec un point central à 12 000.
G29: Pour 2030, je n’ai pas trouvé de prévision publique officielle. Mon estimation ≈ 32 000 est donc une projection tendancielle, fondée sur la stabilité observée entre 2020-2021 et 2024-2025, plutôt qu’une prévision administrative publiée.
... G35: Je peux aussi vous transformer ça en tableau “rapport/Excel-ready” avec trois colonnes : valeur, statut (officiel ou estimé), justification.
B39: 10 | C39: Enfance, enseignement et jeunesse | D39: Enseignement supérieur | E39: Universités | G39: Je vais repartir sur une base plus nette ici, car pour les universités il existe normalement des séries officielles plus stables que pour les ALSH. Je cherche d’abord le décompte institutionnel exact par année, puis je ferai une projection 2030 séparée du constat historique.
G41: J’ai la base juridique actuelle sous la main. Le point délicat maintenant, ce sont les années intermédiaires, parce que le nombre dépend des fusions, scissions et changements de statut (par exemple certains établissements sortent de la catégorie “université” pour devenir “grand établissement”).
G43: Réflexion durant 6m 47s
G45: Oui. En prenant “universités” au sens juridique du code de l’éducation (et non l’ensemble des établissements du supérieur), j’estimerais le tableau suivant pour la France :
G47: Année | H47: Nombre d’universités
G48: 2000 | H48: 82
G49: 2005 | H49: 81
G50: 2010 | H50: 79
G51: 2015 | H51: ≈ 71
G52: 2020 | H52: 59
G53: 2025 | H53: 45
G54: 2030 (prévision centrale) | H54: ≈ 42
G56: Lecture rapide :
G58: 2000 : 82. C’est le décompte direct du décret de classification du 15 mars 2000, qui énumère les universités une par une.
G59: 2005 : 81. La principale rupture entre 2000 et 2005 est le passage de Paris-IX Dauphine au statut de grand établissement par le décret du 26 février 2004 ; on retire donc 1 université au total de 2000.
G60: 2010 : 79. À la baisse liée à Dauphine s’ajoute la fusion de Strasbourg-I, II et III en une seule Université de Strasbourg en 2009, soit un effet net de –2. On passe donc de 81 à 79.
G61: 2015 : ≈ 71. Le meilleur point solide trouvé est la version en vigueur au 1er janvier 2016 de l’article D711-1, qui énumère 71 universités. Ce niveau est cohérent avec les grandes fusions antérieures : Aix-Marseille en 2012, Université de Lorraine en 2012 sous statut de grand établissement, ainsi que les réorganisations Bordeaux / Guyane / Montpellier intervenues avant 2016. Pour un “repère 2015”, je retiens donc environ 71.
G62: 2020 : 59. La version en vigueur du 1er janvier 2020 au 1er janvier 2021 de l’article D711-1 permet un décompte direct de 59 universités.
G63: 2025 : 45. La version en vigueur depuis le 1er mars 2025 du même article permet un décompte direct de 45 universités.
G65: Pour 2030, je n’ai pas trouvé de prévision publique officielle du nombre d’universités. La publication officielle de projections du ministère porte sur les effectifs étudiants, pas sur le nombre d’établissements ; elle projette un supérieur autour de 3,1 millions d’inscrits à l’horizon 2030-2033. Du coup, 42 est une projection tendancielle personnelle, fondée sur la poursuite d’une consolidation plus lente qu’entre 2015 et 2025 ; je mettrais une fourchette raisonnable à 40–45.
...

Sheet ERP -Sans sanitaires collectifs
A1: ID | B1: Catégorie chapeau | C1: Catégorie principale | D1: Sous-catégorie | E1: Type ERP principal | F1: Type de classement | G1: Notes de classement | H1: Exemples | I1: ERP / hors ERP / mixte | J1: Accueil du public : oui/non/variable | K1: Présence de sommeil : oui/non/variable | L1: Espaces sanitaires collectifs (WC et/ou douche) | M1: Unité de compte retenue | N1: Nature de la donnée | O1: Niveau de fiabilité | P1: Risque de doublon ERP | Q1: Doublon potentiel avec | R1: Sous-catégorie incluse dans | S1: Justification de stagnation / faible variation | T1: Surface moyenne 2026 (m² / établissement) | U1: Capacité instantanée moyenne 2026 (places/lits/usagers) | V1: Inclure dans Total France (1/0) | W1: Justification de la projection | X1: Sources (URL) | Y1: 2000 | Z1: 2005 | AA1: 2010 | AB1: 2015 | AC1: 2016 | AD1: 2017 | AE1: 2018 | AF1: 2019 | AG1: 2020 | AH1: 2021 | AI1: 2022 | AJ1: 2023 | AK1: 2024 | AL1: 2025 | AM1: 2026 | AN1: 2027 | AO1: 2028 | AP1: 2029 | AQ1: 2030
B2: TOTAL | C2: France | D2: TOTAL FRANCE (formule pilotée par la colonne « Inclure dans Total France (1/0) ») | P2: formule | S2: Le total additionne uniquement les lignes marquées 1 ; vous pouvez modifier ces drapeaux pour inclure/exclure des sous-catégories. | T2: =IFERROR(SUMPRODUCT($V$3:$V$12,$AM$3:$AM$12,T$3:T$12)/SUMPRODUCT($V$3:$V$12,$AM$3:$AM$12),"") -> 93.364325 | U2: =IFERROR(SUMPRODUCT($V$3:$V$12,$AM$3:$AM$12,U$3:U$12)/SUMPRODUCT($V$3:$V$12,$AM$3:$AM$12),"") -> 14.724334 | V2: - | Y2: =SUMPRODUCT($V$3:$V$12,Y$3:Y$12) -> 23882 | Z2: =SUMPRODUCT($V$3:$V$12,Z$3:Z$12) -> 23051 | AA2: =SUMPRODUCT($V$3:$V$12,AA$3:AA$12) -> 22448 | AB2: =SUMPRODUCT($V$3:$V$12,AB$3:AB$12) -> 22059 | AC2: =SUMPRODUCT($V$3:$V$12,AC$3:AC$12) -> 22006 | AD2: =SUMPRODUCT($V$3:$V$12,AD$3:AD$12) -> 21961 | AE2: =SUMPRODUCT($V$3:$V$12,AE$3:AE$12) -> 21922 | AF2: =SUMPRODUCT($V$3:$V$12,AF$3:AF$12) -> 21893 | ... AQ2: =SUMPRODUCT($V$3:$V$12,AQ$3:AQ$12) -> 21774
A3: 1 | B3: Enfance, enseignement et jeunesse | C3: Formation | D3: Auto-écoles | E3: R ou W | F3: ERP | G3: Classement selon activité dominante et configuration. | H3: Auto-école avec salle de cours | I3: ERP | J3: variable | K3: non | L3: non | M3: site / établissement principal | N3: proxy public / estimation encadrée | O3: faible | P3: non | S3: Pas de stagnation structurelle : la série évolue à la baisse sur la période 2000-2026 ; la projection prolonge cette tendance avec prudence. | T3: 120 | U3: 20 | V3: 1 | W3: proxy SIRUS/BPE catégorie école de conduite. Dynamique projetée 2027-2030: baisse légère. Fiabilité: faible. | X3: https://www.insee.fr/fr/metadonnees/source/fichier/BPE_evol_1924_liste_a_plat_TYPEQU.html | Y3: 14894 | Z3: 14164 | AA3: 13470 | AB3: 12810 | AC3: 12682 | AD3: 12555 | AE3: 12429 | AF3: 12305 | AG3: 12243 | AH3: 12182 | AI3: 12121 | AJ3: 12060 | AK3: 12000 | AL3: 11940 | AM3: 11880 | AN3: 11821 | AO3: 11762 | AP3: 11703 | AQ3: 11644
A4: 2 | B4: Enfance, enseignement et jeunesse | C4: Petite enfance | D4: Haltes-garderies | E4: R | F4: ERP | G4: Accueil occasionnel de jeunes enfants. | H4: Halte-garderie, jardin d’enfants | I4: ERP | J4: oui | K4: non | L4: non | M4: site / établissement principal | N4: proxy public / estimation encadrée | O4: faible | P4: non | S4: Pas de stagnation structurelle : la série évolue à la baisse sur la période 2000-2026 ; la projection prolonge cette tendance avec prudence. | T4: 150 | U4: 20 | V4: 1 | W4: proxy DREES; recul au profit des crèches et micro-crèches. Dynamique projetée 2027-2030: baisse structurelle. Fiabilité: faible. | X4: https://drees.solidarites-sante.gouv.fr/communique-de-presse-jeux-de-donnees/jeux-de-donnees/250528_DATA_donnees-departementales-sur-l-offre-daccueil-du-jeune-enfant-2023 | Y4: 3034 | Z4: 2474 | AA4: 2017 | AB4: 1645 | AC4: 1579 | AD4: 1516 | AE4: 1455 | AF4: 1397 | AG4: 1355 | AH4: 1315 | AI4: 1275 | AJ4: 1237 | AK4: 1200 | AL4: 1164 | AM4: 1129 | AN4: 1095 | AO4: 1062 | AP4: 1030 | AQ4: 999
A5: 3 | B5: Enfance, enseignement et jeunesse | C5: Petite enfance | D5: Jardins d’enfants | E5: R | F5: ERP | G5: Relève du secteur enseignement / éveil. | H5: Jardin d’enfants privé | I5: ERP | J5: oui | K5: non | L5: non | M5: site / établissement principal | N5: proxy public / estimation encadrée | O5: faible | P5: non | S5: Pas de stagnation structurelle : la série évolue à la baisse sur la période 2000-2026 ; la projection prolonge cette tendance avec prudence. | T5: 200 | U5: 30 | V5: 1 | W5: estimation sectorielle. Dynamique projetée 2027-2030: baisse structurelle. Fiabilité: faible. | X5: https://drees.solidarites-sante.gouv.fr/communique-de-presse-jeux-de-donnees/jeux-de-donnees/250528_DATA_donnees-departementales-sur-l-offre-daccueil-du-jeune-enfant-2023 | Y5: 633 | Z5: 516 | AA5: 421 | AB5: 343 | AC5: 329 | AD5: 316 | AE5: 303 | AF5: 291 | AG5: 282 | AH5: 274 | AI5: 266 | AJ5: 258 | AK5: 250 | AL5: 242 | AM5: 235 | AN5: 228 | AO5: 221 | AP5: 214 | AQ5: 208
A6: 4 | B6: Santé et médico-social | C6: Médico-social | D6: Autres établissements spécialisés pour personnes âgées | E6: Variable | F6: Cas particulier | G6: Catégorie de regroupement pour structures spécialisées non couvertes ailleurs ; classement selon l’activité dominante, le niveau de soins, l’hébergement et l’ouverture au public. | H6: Petite unité de vie, maison d’accueil rurale, structure spécialisée seniors | I6: mixte | J6: variable | K6: variable | L6: non | M6: site / établissement principal | N6: proxy résiduel / catégorie non homogène | O6: faible | P6: oui | Q6: EHPAD ; Résidences autonomie / foyers-logements ; USLD | R6: EHPAD ; Résidences autonomie / foyers-logements ; USLD | S6: Faute de série nationale homogène publiée annuellement pour cette sous-catégorie, le proxy est lissé ; la faible variation reflète une prudence méthodologique. | T6: 1200 | U6: 25 | V6: 0 | W6: Catégorie résiduelle et hétérogène ; la projection reste plate par prudence pour éviter des doubles comptes. Fiabilité: faible. | X6: https://drees.solidarites-sante.gouv.fr/jeux-de-donnees/jeux-de-donnees/les-residents-en-etablissements-dhebergement-pour-personnes-agees | Y6: 650 | Z6: 650 | AA6: 650 | AB6: 650 | AC6: 650 | AD6: 650 | AE6: 650 | AF6: 650 | AG6: 650 | AH6: 650 | AI6: 650 | AJ6: 650 | AK6: 650 | AL6: 650 | AM6: 650 | AN6: 650 | AO6: 650 | AP6: 650 | AQ6: 650
A7: 5 | B7: Santé et médico-social | C7: Médico-social | D7: Habitat inclusif / habitats regroupés seniors | E7: Variable | F7: Cas particulier | G7: Logements privatifs avec espaces partagés et projet de vie sociale ; le classement dépend de la configuration immobilière et de l’ouverture au public. | H7: Habitat inclusif seniors, béguinage, habitat regroupé seniors | I7: mixte | J7: variable | K7: oui | L7: non | M7: site / établissement principal | N7: proxy habitat accompagné / estimation encadrée | O7: faible | P7: oui | Q7: Résidences autonomie / foyers-logements ; Résidences services seniors | S7: Pas de stagnation structurelle : la série évolue à la hausse sur la période 2000-2026 ; la projection prolonge cette tendance avec prudence. | T7: 500 | U7: 12 | V7: 1 | W7: Catégorie en développement mais encore mal couverte statistiquement ; projection modérément haussière. Fiabilité: faible. | X7: https://drees.solidarites-sante.gouv.fr/sites/default/files/2025-09/PAPH%20-%20Fiche%2009%20-%20Les%20%C3%A9tablissements%20d%E2%80%99h%C3%A9bergement%20pour%20personnes%20%C3%A2g%C3%A9es_0.pdf | Y7: 95 | Z7: 127 | AA7: 170 | AB7: 228 | AC7: 242 | AD7: 257 | AE7: 272 | AF7: 288 | AG7: 299 | AH7: 311 | AI7: 324 | AJ7: 337 | AK7: 350 | AL7: 362 | AM7: 375 | AN7: 388 | AO7: 402 | AP7: 416 | AQ7: 431
A8: 6 | B8: Santé et médico-social | C8: Médico-social | D8: Hébergements temporaires seniors | E8: Variable | F8: Cas particulier | G8: Accueil temporaire pour personnes âgées, souvent adossé à un EHPAD ou à une autre structure ; classement selon l’établissement support et l’exploitation. | H8: Hébergement temporaire, accueil de répit avec nuitées | I8: mixte | J8: oui | K8: variable | L8: non | M8: site / établissement principal | N8: sous-produit de structures seniors / proxy non additif | O8: faible | P8: oui | Q8: EHPAD ; Résidences autonomie / foyers-logements ; Résidences services seniors | R8: EHPAD ; Résidences autonomie / foyers-logements ; Résidences services seniors | S8: Pas de stagnation structurelle : la série évolue à la hausse sur la période 2000-2026 ; la projection prolonge cette tendance avec prudence. | T8: 700 | U8: 15 | V8: 0 | W8: L’hébergement temporaire est souvent adossé à d’autres structures seniors ; projection en légère hausse mais non additive. Fiabilité: faible. | X8: https://drees.solidarites-sante.gouv.fr/jeux-de-donnees/jeux-de-donnees/les-residents-en-etablissements-dhebergement-pour-personnes-agees | Y8: 1437 | Z8: 1587 | AA8: 1752 | AB8: 1934 | AC8: 1973 | AD8: 2012 | AE8: 2052 | AF8: 2093 | AG8: 2114 | AH8: 2135 | AI8: 2157 | AJ8: 2178 | AK8: 2200 | AL8: 2222 | AM8: 2244 | AN8: 2266 | AO8: 2289 | AP8: 2312 | AQ8: 2335
A9: 7 | B9: Culture, patrimoine et événementiel | C9: Documentation | D9: Centres de documentation | E9: S | F9: ERP | G9: Consultation documentaire. | H9: Centre de documentation spécialisé | I9: ERP | J9: oui | K9: non | L9: non | M9: site / établissement principal | N9: proxy public / stock documentaire spécifique | O9: faible | P9: oui | Q9: Bibliothèques / médiathèques | R9: Bibliothèques / médiathèques (lorsqu’il s’agit d’un service interne) | S9: Faute de série nationale homogène publiée annuellement pour cette sous-catégorie, le proxy est lissé ; la faible variation reflète une prudence méthodologique. | T9: 250 | U9: 20 | V9: 0 | W9: Série conservatrice ; le stock autonome de centres de documentation varie peu et se recoupe parfois avec bibliothèques/médiathèques. Fiabilité: faible. | X9: https://www.insee.fr/fr/metadonnees/source/serie/s1161 | Y9: 1675 | Z9: 1634 | AA9: 1594 | AB9: 1555 | AC9: 1547 | AD9: 1539 | AE9: 1531 | AF9: 1523 | AG9: 1518 | AH9: 1514 | AI9: 1509 | AJ9: 1505 | AK9: 1500 | AL9: 1496 | AM9: 1492 | AN9: 1488 | AO9: 1484 | AP9: 1480 | AQ9: 1476
A10: 8 | B10: Commerce, restauration et loisirs | C10: Commerce | D10: Showrooms / halls de vente | E10: M | F10: ERP | G10: Vente et démonstration. | H10: Showroom automobile, showroom ameublement | I10: ERP | J10: oui | K10: non | L10: non | M10: site / établissement principal | N10: proxy commerce spécialisé / estimation encadrée | O10: faible | P10: oui | Q10: Centres commerciaux / malls ; Industrie + logistique + stockage | S10: Faute de série nationale homogène publiée annuellement pour cette sous-catégorie, le proxy est lissé ; la faible variation reflète une prudence méthodologique. | T10: 800 | U10: 60 | V10: 0 | W10: Proxy large sur les espaces commerciaux de démonstration, conservé stable faute de série nationale homogène. Fiabilité: faible. | X10: https://www.insee.fr/fr/metadonnees/source/serie/s1161 | Y10: 9500 | Z10: 9500 | AA10: 9500 | AB10: 9500 | AC10: 9500 | AD10: 9500 | AE10: 9500 | AF10: 9500 | AG10: 9500 | AH10: 9500 | AI10: 9500 | AJ10: 9500 | AK10: 9500 | AL10: 9500 | AM10: 9500 | AN10: 9500 | AO10: 9500 | AP10: 9500 | AQ10: 9500
A11: 9 | B11: Culte, vie civique et services publics | C11: Administrations / bureaux | D11: Bureaux avec accueil du public | E11: W | F11: ERP | G11: Bureaux avec accueil du public | H11: Immeuble tertiaire, siège administratif | I11: ERP | J11: oui | K11: non | L11: non | M11: site / établissement principal | N11: proxy large / parc tertiaire recevant du public | O11: faible | P11: oui | Q11: Mairies / hôtels de ville ; Maisons France Services / guichets publics ; Préfectures / services administratifs ; Centres de santé / centres médicaux ; Auto-écoles ; Centres de formation / CFA | S11: Faute de série nationale homogène publiée annuellement pour cette sous-catégorie, le proxy est lissé ; la faible variation reflète une prudence méthodologique. | T11: 250 | U11: 20 | V11: 0 | W11: Catégorie volontairement large et non homogène ; le proxy reste stable pour éviter d’additionner plusieurs sous-catégories déjà détaillées. Fiabilité: faible. | X11: https://www.insee.fr/fr/metadonnees/source/serie/s1161 | Y11: 120000 | Z11: 120000 | AA11: 120000 | AB11: 120000 | AC11: 120000 | AD11: 120000 | AE11: 120000 | AF11: 120000 | AG11: 120000 | AH11: 120000 | AI11: 120000 | AJ11: 120000 | AK11: 120000 | AL11: 120000 | AM11: 120000 | AN11: 120000 | AO11: 120000 | AP11: 120000 | AQ11: 120000
A12: 10 | B12: Sanitaires publics | C12: Sanitaires publics | D12: Toilettes publiques (sur la voie publique) | E12: Variable | F12: Souvent équipement isolé / non type autonome | G12: Pas de type ERP autonome. | H12: Sanisette, bloc sanitaires public | I12: mixte | J12: oui | K12: non | L12: non | M12: site / établissement principal | N12: proxy public / estimation encadrée | O12: faible | P12: non | S12: Pas de stagnation structurelle : la série évolue à la hausse sur la période 2000-2026 ; la projection prolonge cette tendance avec prudence. | T12: 25 | U12: 6 | V12: 1 | W12: proxy équipements d’hygiène urbaine. Dynamique projetée 2027-2030: hausse légère. Fiabilité: faible. | X12: https://www.insee.fr/fr/metadonnees/source/serie/s1161 | Y12: 5226 | Z12: 5770 | AA12: 6370 | AB12: 7033 | AC12: 7174 | AD12: 7317 | AE12: 7463 | AF12: 7612 | AG12: 7688 | AH12: 7765 | AI12: 7842 | AJ12: 7921 | AK12: 8000 | AL12: 8080 | AM12: 8161 | AN12: 8243 | AO12: 8325 | AP12: 8408 | AQ12: 8492
A13: =#REF!+1 -> #REF! | B13: Industrie et logistique | C13: Industrie / logistique | D13: Industrie + logistique + stockage | E13: Variable | F13: Souvent hors ERP autonome | G13: Le site industriel, logistique ou de stockage n’est pas un type ERP en soi. | H13: Site industriel avec showroom | I13: mixte | J13: oui | K13: non | L13: variable | M13: site / établissement principal | N13: sous-espace / proxy non additif | O13: faible | P13: non | Q13: Showrooms / halls de vente ; Bureaux avec accueil du public ; Restaurants | S13: Sous-espace rattaché à un site parent ; la série varie peu car elle suit un stock principal administré et non un marché autonome. | T13: 12000 | U13: 120 | V13: 0 | W13: proxy sites industriels/logistiques avec accueil du public. Dynamique projetée 2027-2030: hausse légère. Fiabilité: faible. Risque de doublon: oui si addition avec la catégorie parente ou avec des sous-espaces d’un même site. | X13: https://www.insee.fr/fr/statistiques/2011101 | Y13: 9796 | Z13: 10816 | AA13: 11942 | AB13: 13185 | AC13: 13449 | AD13: 13718 | AE13: 13992 | AF13: 14272 | AG13: 14415 | AH13: 14559 | AI13: 14704 | AJ13: 14851 | AK13: 15000 | AL13: 15150 | AM13: 15302 | AN13: 15455 | AO13: 15610 | AP13: 15766 | AQ13: 15924
B18: Catégorie chapeau | C18: Segment Principal | D18: Sous-Segment | E18: Type ERP principal | F18: Type de classement | G18: Notes de classement | H18: Exemples | I18: ERP Hors ERP Mixte | J18: Accueil Public : oui/non variable | K18: Présence de sommeil (oui-non variable) | L18: Espaces sanitaires collectifs (WC et/ou douche) | M18: Unité de compte retenue | N18: Nature de la donnée | O18: Niveau de fiabilité | P18: Sous-catégorie incluse dans … | AL18: 2025
B19: - | C19: - | D19: - | E19: - | F19: - | G19: - | H19: - | I19: - | J19: - | K19: - | L19: - | M19: - | N19: - | O19: - | P19: - | AL19: -
B20: Commerce, Restauration & Loisirs | C20: Commerce alimentaire de proximité | D20: Boulangeries / pâtisseries artisanales | E20: M | F20: ERP | G20: Petit commerce alimentaire recevant du public. Très fréquent dans le tissu de proximité ; sanitaires publics non systématiques mais sanitaires personnel fréquents. | H20: Boulangerie, pâtisserie, terminal de cuisson | I20: ERP | J20: oui | K20: non | L20: variable | M20: Site / point de vente | N20: estimation de structure / ordre de grandeur | O20: Moyen | AL20: 35000
B21: Commerce, Restauration & Loisirs | C21: Commerce alimentaire de proximité | D21: Boucheries / charcuteries / poissonneries | E21: M | F21: ERP | G21: Petit commerce alimentaire recevant du public ; souvent omis dans les listes macros de grands équipements. | H21: Boucherie, charcuterie, poissonnerie | I21: ERP | J21: oui | K21: non | L21: variable | M21: Site / point de vente | N21: estimation de structure / ordre de grandeur | O21: Moyen | AL21: 12000
